Workbook
Name ARP: '[1]Datos Básicos'!$F$9
Name AT: '[1]Datos Básicos'!$B$6
Name CAJA: '[1]Datos Básicos'!$B$11
Name Cesantia: '[1]Datos Básicos'!$B$19
Name ESAP: '[1]Datos Básicos'!$F$15
Name FonSol1: '[1]Datos Básicos'!$B$26
Name FonSol2: '[1]Datos Básicos'!$B$27
Name FonSol3: '[1]Datos Básicos'!$B$28
Name FonSol4: '[1]Datos Básicos'!$B$29
Name FonSol5: '[1]Datos Básicos'!$B$30
Name FonSol6: '[1]Datos Básicos'!$B$31
Name ICBF: '[1]Datos Básicos'!$B$10
Name IND: '[1]Datos Básicos'!$F$16
Name IntCesantia: '[1]Datos Básicos'!$B$22
Name PensionEmpleado: '[1]Datos Básicos'!$B$16
Name PensionEmpresa: '[1]Datos Básicos'!$C$16
Name Prima: '[1]Datos Básicos'!$B$20
Name SaludEmpleado: '[1]Datos Básicos'!$B$15
Name SaludEmpresa: '[1]Datos Básicos'!$C$15
Name SegmentaciónDeDatos_Años__FECHA__LIQUIDACION: #N/A
Name SENA: '[1]Datos Básicos'!$B$9
Name SM: '[1]Datos Básicos'!$B$5
Name UVT: '[1]Datos Básicos'!$F$11
Name Vacaciones: '[1]Datos Básicos'!$B$21
Name ValorHora: [1]Calculos!$B$4

Sheet GRAFICO LABOR A LABOR
A1: TOP COSTOS POR LABOR 2024 | I1: COSTOS OPERATIVOS MES A MES

Sheet CONSOLIDADO LABOR A LABOR
A1: LABOR | B1: COSTO | C1: QUINCENA | D1: FECHA LIQUIDACION
A2: PICADA | B2: =+SUM([2]CONSOLIDADO!$G$54:$I$54) -> 34726015 | C2: 1 | D2: 45214
A3: ALEMANA | B3: =+[2]CONSOLIDADO!$J$54 -> 5100760 | C3: 1 | D3: 45214 | F3: Etiquetas de fila | G3: Suma de COSTO | J3: =UPPER(F4) -> OCT | K3: =GETPIVOTDATA("COSTO",$F$3,"Meses (FECHA LIQUIDACION)",1) -> #REF!
A4: ALIMENTACION | B4: =+'[2]TOTAL DEFINIT re'!$O$63 -> 12206000 | C4: 1 | D4: 45214 | F4: oct | G4: 1.5390054e+08 | J4: =UPPER(F5) -> NOV | K4: =GETPIVOTDATA("COSTO",$F$3,"Meses (FECHA LIQUIDACION)",2) -> #REF!
A5: REFORCE | B5: =+SUM([2]CONSOLIDADO!$M$54:$N$54) -> 2789255 | C5: 1 | D5: 45214 | F5: nov | G5: 1.578332e+08 | J5: =UPPER(F6) -> DIC | K5: =GETPIVOTDATA("COSTO",$F$3,"Meses (FECHA LIQUIDACION)",10) -> 1.5390054e+08
A6: CANASTA | B6: =+[2]CONSOLIDADO!$O$54 -> 185800 | C6: 1 | D6: 45214 | F6: dic | G6: 1.2349889e+08 | J6: =UPPER(F7) -> TOTAL GENERAL | K6: =GETPIVOTDATA("COSTO",$F$3,"Meses (FECHA LIQUIDACION)",11) -> 1.578332e+08
A7: TRAMO | B7: =+[2]CONSOLIDADO!$P$54 -> 1625100 | C7: 1 | D7: 45214 | F7: Total general | G7: 4.3523263e+08 | J7: =UPPER(F8) | K7: =GETPIVOTDATA("COSTO",$F$3,"Meses (FECHA LIQUIDACION)",12) -> 1.2349889e+08
A8: AVANCE | B8: =+[2]CONSOLIDADO!$S$54 -> 285600 | C8: 1 | D8: 45214
A9: TURNO | B9: =+[2]CONSOLIDADO!$R$54 -> 2614400 | C9: 1 | D9: 45214
A10: LIMPIEZA DE ESCALERAS | B10: =+SUM([2]CONSOLIDADO!$Q$54+[2]CONSOLIDADO!$U$54) -> 113750 | C10: 1 | D10: 45214
A11: GUAYERO | B11: =+[2]CONSOLIDADO!$W$54 -> 2866500 | C11: 1 | D11: 45214 | F11: Años (FECHA LIQUIDACION) | G11: 2024
A12: METRTO INTERCALACION | B12: =+[2]CONSOLIDADO!$Y$54 -> 566400 | C12: 1 | D12: 45214
A13: PUERTA DE INCLIANDO | B13: =+[2]CONSOLIDADO!$X$54 -> 1196000 | C13: 1 | D13: 45214 | F13: Etiquetas de fila | G13: Suma de COSTO
A14: TURNO TMABOR 4 | B14: =+[2]CONSOLIDADO!$Z$54 -> 160000 | C14: 1 | D14: 45214 | F14: ALEMANA | G14: 17594860
A15: MALACATEROS | B15: 3013935 | C15: 1 | D15: 45214 | F15: ALIMENTACION | G15: 51156000
A16: PATIEROS | B16: =+SUM([2]CONSOLIDADO!$AA$43:$AA$44) -> 1724282 | C16: 1 | D16: 45214 | F16: ARCOS DE ACERO | G16: 6856160
A17: PAJARITA | B17: =+[2]CONSOLIDADO!$AA$51 -> 1290000 | C17: 1 | D17: 45214 | F17: CANASTA | G17: 6378900
A18: SOLDADORES | B18: =+SUM('[2]TOTAL DEFINIT re'!$E$60:$E$61) -> 2486000 | C18: 1 | D18: 45214 | F18: COCHES DE ROCA | G18: 2036890
A19: REUBICADO (EVARISTO) | B19: =+'[2]TOTAL DEFINIT re'!$E$28 -> 734490 | C19: 1 | D19: 45214 | F19: GUAYERO | G19: 7112000
A20: PICADA | B20: =+SUM([3]CONSOLIDADO!$C$54:$E$54) -> 42080288 | C20: 2 | D20: 45230 | F20: LIMPIEZA DE ESCALERAS | G20: 1870246
A21: ALEMANA | B21: =+[3]CONSOLIDADO!$F$54 -> 3700900 | C21: 2 | D21: 45230 | F21: LIMPIEZA DE POZO | G21: 600000
A22: ALIMENTACION | B22: =+'[3]TOTAL DEFINIT '!$W$58 -> 12979500 | C22: 2 | D22: 45230 | F22: LIMPIEZA DE TRAMO | G22: 836800
A23: REFORCE | B23: =+[3]CONSOLIDADO!$I$54 -> 2059680 | C23: 2 | D23: 45230 | F23: MALACATEROS | G23: 8349502.2 | I23: =+F15 -> ALIMENTACION | J23: =+GETPIVOTDATA("COSTO",$F$13,"LABOR","ALEMANA") -> 17594860
A24: CANASTA | B24: =+[3]CONSOLIDADO!$J$54 -> 52800 | C24: 2 | D24: 45230 | F24: METRO DE ROCA | G24: 8351200 | I24: =+F28 -> PICADA | J24: =+GETPIVOTDATA("COSTO",$F$13,"LABOR","PICADA") -> 1.310503e+08
A25: TRAMO | B25: =+[3]CONSOLIDADO!$K$54 -> 1945600 | C25: 2 | D25: 45230 | F25: METRO DESPATE | G25: 18062800 | I25: MALACATEROS | J25: =+GETPIVOTDATA("COSTO",$F$13,"LABOR","MALACATEROS") -> 8349502.2
A26: TURNO | B26: =+[3]CONSOLIDADO!$M$54 -> 1536100 | C26: 2 | D26: 45230 | F26: PAJARITA | G26: 3983759.7 | I26: =+F14 -> ALEMANA | J26: =+GETPIVOTDATA("COSTO",$F$13,"LABOR","ALEMANA") -> 17594860
A27: METRO DE ROCA | B27: =+[3]CONSOLIDADO!$O$54 -> 1090800 | C27: 2 | D27: 45230 | F27: PATIEROS | G27: 4633950.9 | I27: =+F25 -> METRO DESPATE | J27: =+GETPIVOTDATA("COSTO",$F$13,"LABOR","METRO DESPATE") -> 18062800
A28: LIMPIEZA DE ESCALERAS | B28: =+[3]CONSOLIDADO!$L$54+[3]CONSOLIDADO!$P$54 -> 769953.1 | C28: 2 | D28: 45230 | F28: PICADA | G28: 1.310503e+08 | I28: =+F35 -> TURNO | J28: =+GETPIVOTDATA("COSTO",$F$13,"LABOR","TURNO") -> 11651700
A29: LIMPIEZA POZO | B29: =+[3]CONSOLIDADO!$Q$54 -> 300000 | C29: 2 | D29: 45230 | F29: PLACA MALACATE INTER | G29: 150000
A30: GUAYERO | B30: =+[3]CONSOLIDADO!$R$54 -> 3363500 | C30: 2 | D30: 45230 | F30: PUERTA INCLIANDO | G30: 332000
A31: METRTO INTERCALACION | B31: =+[2]CONSOLIDADO!$Y$54 -> 566400 | C31: 2 | D31: 45230 | F31: REFORCE | G31: 10302135
A32: PUERTA DE INCLIANDO | B32: =+[3]CONSOLIDADO!$S$54 -> 400000 | C32: 2 | D32: 45230 | F32: REUBICADO (EVARISTO) | G32: 2049791.1
A33: TURNO TMABOR 4 | B33: =+[3]CONSOLIDADO!$U$54 -> 33000 | C33: 2 | D33: 45230 | F33: SOLDADORES | G33: 8203800
A34: MALACATEROS | B34: 3039472 | C34: 2 | D34: 45230 | F34: TRAMO | G34: 6203200
A35: PATIEROS | B35: =+SUM([3]CONSOLIDADO!$V$45:$V$46) -> 1650188 | C35: 2 | D35: 45230 | F35: TURNO | G35: 11651700
A36: PAJARITA | B36: =+[3]CONSOLIDADO!$V$51 -> 1289260 | C36: 2 | D36: 45230 | F36: TURNO DICIEMBRE | G36: 360000
A37: SOLDADORES | B37: =+SUM('[3]TOTAL DEFINIT '!$E$55:$E$56) -> 2624320 | C37: 2 | D37: 45230 | F37: COCHE ROCA | G37: 122500
A38: REUBICADO (EVARISTO) | B38: =+'[3]TOTAL DEFINIT '!$E$35 -> 734490 | C38: 2 | D38: 45230 | F38: coches guayados | G38: 3164000
A39: PICADA | B39: =+SUM([4]CONSOLIDADO!$C$55:$F$55) -> 35337750 | C39: 1 | D39: 45245 | F39: ARCO DE ACERO | G39: 528000
A40: ALEMANA | B40: =+[4]CONSOLIDADO!$G$55 -> 2793000 | C40: 1 | D40: 45245 | F40: coche de basura y madera | G40: 116550
...

Sheet resumen trimestral
A1: A
E2: TOP 3 cotos generales 2024
E3: MES | F3: % | G3: ACTIVIDAD
E4: ENERO | F4: 36.65 | G4: PICADA
F5: 8.0483969 | G5: BONO ALIMENTACION
F6: 6.4108269 | G6: SOSTENIMIENTO
E7: FEBRERO | F7: 46.035395 | G7: PICADA
F8: 16.473914 | G8: BONO ALIMENTACION
F9: 9.9877387 | G9: MOVIMIENTO DE ROCA
E10: MARZO | F10: 44.297288 | G10: PICADA
F11: 16.209453 | G11: BONO ALIMENTACION
F12: 10.735515 | G12: SOSTENIMIENTO
E13: MAYO | F13: 48.501537 | G13: PICADA
F14: 11.907314 | G14: BONO ALIMENTACION
F15: 10.161381 | G15: PERSONAL DE APOYO
E16: JUNIO | F16: 51.241718 | G16: PICADA
F17: 12.222268 | G17: BONO ALIMENTACION
F18: 7.7 | G18: PERSONAL DE APOYO
E19: JULIO | F19: 47.963941 | G19: PICADA
F20: 12.599435 | G20: BONO ALIMENTACION
F21: 7.5247089 | G21: PERSONAL DE APOYO
E22: AGOSTO | F22: 51.885365 | G22: PICADA
F23: 14.012363 | G23: BONO ALIMENTACION
F24: 6.7886316 | G24: MOVIEMIENTO DE ROCA
E25: SEPTIEMBRE | F25: 45.891438 | G25: PICADA
F26: 16.84118 | G26: BONO ALIMENTACION
F27: 9.9049593 | G27: PERSONAL DE APOYO
E28: OCTUBRE

Sheet PRODUC ACUMULADA
A2: PRODUCCION MES
A4: MES | B4: PRODUCCION
A5: ENERO | B5: =+'[40]Daily Report ENERO'!M42 -> 1698.66
A6: FEBRERO | B6: =+'[41]PRODUC ACUMULADA'!$B$6 -> 1830.15
A7: MARZO | B7: =+'[42]PRODUC ACUMULADA'!$B$7 -> 1898.77
A8: ABRIL | B8: 1800.91
A9: MAYO | B9: =+'[43]PRODUC ACUMULADA'!$B$9 -> 1964.11
A10: JUNIO | B10: =+'[40]Daily Report JUNIO '!M43 -> 0
A11: JULIO | B11: =+'[40]Daily Report JULIO'!N45 -> 0
A12: AGOSTO | B12: =+'[40]Daily Report AGOSTO'!M41 -> 0
A13: SEPTIEMBRE | B13: =+'[40]Daily Report SEPTIEMBRE'!M41 -> 0
A14: OCTUBRE | B14: =+'[40]Daily Report OCTUBRE'!M41 -> 0
A15: NOVIEMBRE | B15: =+'[40]Daily Report NOVIEMBRE'!M40 -> 0
A16: DICIEMBRE | B16: =+'[40]Daily Report DICIEMBRE'!M41 -> 0
A17: TOTAL | B17: =SUM(B5:B16) -> 9192.6

Sheet RESUMEN 2026
A1: MES | B1: LABOR | C1: COSTO | D1: % | F1: MES | G1: LABOR | H1: COSTO | I1: % | K1: MES | L1: LABOR | M1: COSTO | N1: % | Q1: MES | R1: LABOR | S1: COSTO | T1: % | W1: MES | X1: LABOR | Y1: COSTO | Z1: % | AD1: MES | AE1: LABOR | AF1: COSTO | AG1: % | AK1: MES | AL1: LABOR | AM1: COSTO | AN1: % | AS1: MES | AT1: LABOR | AU1: COSTO | AV1: % | BA1: MES | BB1: LABOR | BC1: COSTO | BD1: % | BH1: MES | BI1: LABOR | BJ1: COSTO | BK1: % | BO1: MES | BP1: LABOR | BQ1: COSTO | BR1: % | BV1: MES | BW1: LABOR | BX1: COSTO | BY1: %
A2: ENERO | B2: PICADA | C2: =+'[44]CONSOLIDADO LABOR'!B552+'[44]CONSOLIDADO LABOR'!B572 -> 62821079 | D2: =+(C2*100)/$C$17 -> 45.834563 | F2: FEBRERO | G2: PICADA | H2: =+'[44]CONSOLIDADO LABOR'!B592+'[44]CONSOLIDADO LABOR'!B612 -> 65801446 | I2: =+(H2*100)/$H$18 -> 49.04646 | K2: MARZO | L2: PICADA | M2: 60017884 | N2: 40.340044 | Q2: ABRIL | R2: PICADA | S2: 58199567 | T2: =+(S2*100)/S22 -> 38.061669 | W2: MAYO | X2: PICADA | Y2: 63934306 | Z2: =+(Y2*100)/Y21 -> 68.388283 | AD2: JUNIO | AE2: PICADA | AF2: 0 | AG2: =+(AF2*100)/$AF$18 -> #DIV/0! | AK2: JULIO | AL2: PICADA | AM2: 0 | AN2: =+(AM2*100)/$AM$18 -> #DIV/0! | AS2: AGOSTO | AT2: PICADA | AU2: 0 | AV2: =+(AU2*100)/AU21 -> #DIV/0! | BA2: SEPTIEMBRE | BB2: PICADA | BC2: 0 | BD2: =+(BC2*100)/BC21 -> #DIV/0! | BH2: OCTUBRE | BI2: PICADA | BJ2: 0 | BK2: =+(BJ2*100)/BJ22 -> #DIV/0! | BO2: NOVIEMBRE | BP2: PICADA | BQ2: 0 | BR2: =+(BQ2*100)/BQ22 -> #DIV/0! | BV2: DICIEMBRE | BW2: PICADA | BX2: 0 | BY2: =+(BX2*100)/BX22 -> #DIV/0!
B3: BONO ALIMENTACION | C3: =+'[44]CONSOLIDADO LABOR'!B554+'[44]CONSOLIDADO LABOR'!B574 -> 34100750 | D3: =+(C3*100)/$C$17 -> 24.880072 | G3: BONO ALIMENTACION | H3: =+'[44]CONSOLIDADO LABOR'!B41+'[44]CONSOLIDADO LABOR'!B60 -> 25661500 | I3: =+(H3*100)/$H$18 -> 19.127327 | L3: ALEMANA | M3: 7073528 | N3: 4.7543567 | R3: ALEMANA | S3: 8076073 | T3: =+(S3*100)/S22 -> 5.2816341 | X3: ALEMANA | Y3: 10412790 | Z3: =+(Y3*100)/Y21 -> 11.138196 | AE3: BONO ALIMENTACION | AF3: 0 | AG3: =+(AF3*100)/$AF$18 -> #DIV/0! | AL3: BONO ALIMENTACION | AM3: 0 | AN3: =+(AM3*100)/$AM$18 -> #DIV/0! | AT3: ALEMANA | AU3: 0 | AV3: =+(AU3*100)/AU21 -> #DIV/0! | BB3: ALEMANA | BC3: 0 | BD3: =+(BC3*100)/BC21 -> #DIV/0! | BI3: ALEMANA | BJ3: 0 | BK3: =+(BJ3*100)/BJ22 -> #DIV/0! | BP3: ALEMANA | BQ3: 0 | BR3: =+(BQ3*100)/BQ22 -> #DIV/0! | BW3: ALEMANA | BX3: 0 | BY3: =+(BX3*100)/BX22 -> #DIV/0!
B4: PERSONAL DE APOYO | C4: =+'[44]CONSOLIDADO LABOR'!B566+'[44]CONSOLIDADO LABOR'!B567+'[44]CONSOLIDADO LABOR'!B568+'[44]CONSOLIDADO LABOR'!B586+'[44]CONSOLIDADO LABOR'!B587+'[44]CONSOLIDADO LABOR'!B588 -> 10288630 | D4: =+(C4*100)/$C$17 -> 7.5066342 | G4: PERSONAL DE APOYO | H4: =+'[44]CONSOLIDADO LABOR'!B606+'[44]CONSOLIDADO LABOR'!B607+'[44]CONSOLIDADO LABOR'!B608+'[44]CONSOLIDADO LABOR'!B626+'[44]CONSOLIDADO LABOR'!B627+'[44]CONSOLIDADO LABOR'!B628 -> 13384885 | I4: =+(H4*100)/$H$18 -> 9.976699 | L4: ALIMENTACION | M4: 21459750 | N4: 14.423822 | R4: ALIMENTACION | S4: 30371250 | T4: =+(S4*100)/S22 -> 19.862355 | X4: REFORCE | Y4: 600625 | Z4: =+(Y4*100)/Y21 -> 0.64246749 | AE4: MOVIMIENTO DE ROCA | AF4: 0 | AG4: =+(AF4*100)/$AF$18 -> #DIV/0! | AL4: PERSONAL DE APOYO | AM4: 0 | AN4: =+(AM4*100)/$AM$18 -> #DIV/0! | AT4: ALIMENTACION | AU4: 0 | AV4: =+(AU4*100)/AU21 -> #DIV/0! | BB4: ALIMENTACION | BC4: 0 | BD4: =+(BC4*100)/BC21 -> #DIV/0! | BI4: ALIMENTACION | BJ4: 0 | BK4: =+(BJ4*100)/BJ22 -> #DIV/0! | BP4: ALIMENTACION | BQ4: 0 | BR4: =+(BQ4*100)/BQ22 -> #DIV/0! | BW4: ALIMENTACION | BX4: 0 | BY4: =+(BX4*100)/BX22 -> #DIV/0!
B5: MOVIEMIENTO ROCA | C5: =+'[44]CONSOLIDADO LABOR'!B559+'[44]CONSOLIDADO LABOR'!B563+'[44]CONSOLIDADO LABOR'!B579+'[44]CONSOLIDADO LABOR'!B580 -> 6610399 | D5: =+(C5*100)/$C$17 -> 4.8229791 | G5: MALACATEROS | H5: =+'[44]CONSOLIDADO LABOR'!B605+'[44]CONSOLIDADO LABOR'!B625 -> 6392748.3 | I5: =+(H5*100)/$H$18 -> 4.7649664 | L5: REFORCE | M5: 3255550 | N5: 2.1881649 | R5: REFORCE | S5: 1117950 | T5: =+(S5*100)/S22 -> 0.73112301 | X5: VENTANA | Y5: 4900000 | Z5: =+(Y5*100)/Y21 -> 5.2413581 | AE5: PERSONAL DE APOYO | AF5: 0 | AG5: =+(AF5*100)/$AF$18 -> #DIV/0! | AL5: MOVIMIENTO DE ROCA | AM5: 0 | AN5: =+(AM5*100)/$AM$18 -> #DIV/0! | AT5: REFORCE | AU5: 0 | AV5: =+(AU5*100)/AU21 -> #DIV/0! | BB5: REFORCE | BC5: 0 | BD5: =+(BC5*100)/BC21 -> #DIV/0! | BI5: REFORCE | BJ5: 0 | BK5: =+(BJ5*100)/BJ22 -> #DIV/0! | BP5: REFORCE | BQ5: 0 | BR5: =+(BQ5*100)/BQ22 -> #DIV/0! | BW5: REFORCE | BX5: 0 | BY5: =+(BX5*100)/BX22 -> #DIV/0!
B6: MALACATEROS | C6: =+'[44]CONSOLIDADO LABOR'!B565+'[44]CONSOLIDADO LABOR'!B585 -> 5432956 | D6: =+(C6*100)/$C$17 -> 3.963911 | G6: COCHES GUAYADOS | H6: =+'[44]CONSOLIDADO LABOR'!B602+'[44]CONSOLIDADO LABOR'!B622 -> 5939500 | I6: =+(H6*100)/$H$18 -> 4.4271284 | L6: ventana | M6: 4400000 | N6: 2.9573884 | R6: ventana | S6: 4550000 | T6: =+(S6*100)/S22 -> 2.9756337 | X6: PUERTA DE INCLINADO | Y6: 0 | Z6: =+(Y6*100)/Y21 -> 0 | AE6: MALACATEROS | AF6: 0 | AG6: =+(AF6*100)/$AF$18 -> #DIV/0! | AL6: MALACATEROS | AM6: 0 | AN6: =+(AM6*100)/$AM$18 -> #DIV/0! | AT6: CANASTA | AU6: 0 | AV6: =+(AU6*100)/AU21 -> #DIV/0! | BB6: CANASTA | BC6: 0 | BD6: =+(BC6*100)/BC21 -> #DIV/0! | BI6: ventana | BJ6: 0 | BK6: =+(BJ6*100)/BJ22 -> #DIV/0! | BP6: ventana | BQ6: 0 | BR6: =+(BQ6*100)/BQ22 -> #DIV/0! | BW6: ventana | BX6: 0 | BY6: =+(BX6*100)/BX22 -> #DIV/0!
B7: =+G8 -> MOVIMIENTO DE ROCA | C7: =+'[44]CONSOLIDADO LABOR'!B562+'[44]CONSOLIDADO LABOR'!B582 -> 5089000 | D7: =+(C7*100)/$C$17 -> 3.712959 | G7: BONIFICACION | H7: =+'[44]CONSOLIDADO LABOR'!B611+'[44]CONSOLIDADO LABOR'!B631 -> 4814140 | I7: =+(H7*100)/$H$18 -> 3.5883182 | L7: puerta de inclinado | M7: 318100 | N7: 0.21380574 | R7: puerta de inclinado | S7: 743500 | T7: =+(S7*100)/S22 -> 0.48623817 | X7: TRAMO | Y7: 1841400 | Z7: =+(Y7*100)/Y21 -> 1.969681 | AE7: COCHES GUAYADOS | AF7: 0 | AG7: =+(AF7*100)/$AF$18 -> #DIV/0! | AL7: COCHES GUAYADOS | AM7: 0 | AN7: =+(AM7*100)/$AM$18 -> #DIV/0! | AT7: TRAMO | AU7: 0 | AV7: =+(AU7*100)/AU21 -> #DIV/0! | BB7: TRAMO | BC7: 0 | BD7: =+(BC7*100)/BC21 -> #DIV/0! | BI7: CANASTA | BJ7: 0 | BK7: =+(BJ7*100)/BJ22 -> #DIV/0! | BP7: puerta de inclinado | BQ7: 0 | BR7: =+(BQ7*100)/BQ22 -> #DIV/0! | BW7: puerta de inclinado | BX7: 0 | BY7: =+(BX7*100)/BX22 -> #DIV/0!
B8: SOSTENIMIENTO | C8: =+'[44]CONSOLIDADO LABOR'!B553+'[44]CONSOLIDADO LABOR'!B555+'[44]CONSOLIDADO LABOR'!B556+'[44]CONSOLIDADO LABOR'!B573+'[44]CONSOLIDADO LABOR'!B575+'[44]CONSOLIDADO LABOR'!B576 -> 5045450 | D8: =+(C8*100)/$C$17 -> 3.6811847 | G8: MOVIMIENTO DE ROCA | H8: =+'[44]CONSOLIDADO LABOR'!B599+'[44]CONSOLIDADO LABOR'!B603+'[44]CONSOLIDADO LABOR'!B619+'[44]CONSOLIDADO LABOR'!B623 -> 4131000 | I8: =+(H8*100)/$H$18 -> 3.0791258 | L8: TRAMO | M8: 2292050 | N8: 1.5405641 | R8: TRAMO | S8: 1749200 | T8: =+(S8*100)/S22 -> 1.1439513 | X8: TURNO | Y8: 1753400 | Z8: =+(Y8*100)/Y21 -> 1.8755505 | AE8: TURNOS | AF8: 0 | AG8: =+(AF8*100)/$AF$18 -> #DIV/0! | AL8: SOSTENIMIENTO | AM8: 0 | AN8: =+(AM8*100)/$AM$18 -> #DIV/0! | AT8: TURNO | AU8: 0 | AV8: =+(AU8*100)/AU21 -> #DIV/0! | BB8: TURNO | BC8: 0 | BD8: =+(BC8*100)/BC21 -> #DIV/0! | BI8: TRAMO | BJ8: 0 | BK8: =+(BJ8*100)/BJ22 -> #DIV/0! | BP8: TRAMO | BQ8: 0 | BR8: =+(BQ8*100)/BQ22 -> #DIV/0! | BW8: TRAMO | BX8: 0 | BY8: =+(BX8*100)/BX22 -> #DIV/0!
B9: TURNOS | C9: =+'[44]CONSOLIDADO LABOR'!B558+'[44]CONSOLIDADO LABOR'!B578 -> 3831630 | D9: =+(C9*100)/$C$17 -> 2.7955758 | G9: TURNOS | H9: =+'[44]CONSOLIDADO LABOR'!B598+'[44]CONSOLIDADO LABOR'!B610+'[44]CONSOLIDADO LABOR'!B618+'[44]CONSOLIDADO LABOR'!B630 -> 3382000 | I9: =+(H9*100)/$H$18 -> 2.5208432 | L9: TURNO | M9: 4796050 | N9: 3.2235869 | R9: TURNO | S9: 5741275.3 | T9: =+(S9*100)/S22 -> 3.7547104 | X9: METRO DE ROCA | Y9: 2988300.3 | Z9: =+(Y9*100)/Y21 -> 3.19648 | AE9: SOSTENIMIENTO | AF9: 0 | AG9: =+(AF9*100)/$AF$18 -> #DIV/0! | AL9: TURNOS | AM9: 0 | AN9: =+(AM9*100)/$AM$18 -> #DIV/0! | AT9: METRO DE roca | AU9: 0 | AV9: =+(AU9*100)/AU21 -> #DIV/0! | BB9: METRO DE roca | BC9: 0 | BD9: =+(BC9*100)/BC21 -> #DIV/0! | BI9: TURNO | BJ9: 0 | BK9: =+(BJ9*100)/BJ22 -> #DIV/0! | BP9: TURNO | BQ9: 0 | BR9: =+(BQ9*100)/BQ22 -> #DIV/0! | BW9: TURNO | BX9: 0 | BY9: =+(BX9*100)/BX22 -> #DIV/0!
B10: BONIFICACION | C10: =+'[44]CONSOLIDADO LABOR'!B571+'[44]CONSOLIDADO LABOR'!B591 -> 3723270 | D10: =+(C10*100)/$C$17 -> 2.7165158 | G10: SOSTENIMIENTO | H10: =+'[44]CONSOLIDADO LABOR'!B593+'[44]CONSOLIDADO LABOR'!B595+'[44]CONSOLIDADO LABOR'!B613+'[44]CONSOLIDADO LABOR'!B615 -> 3170410 | I10: =+(H10*100)/$H$18 -> 2.3631303 | L10: METRO DE roca | M10: 6040100 | N10: 4.0597549 | R10: METRO DE roca | S10: 4674800 | T10: =+(S10*100)/S22 -> 3.0572511 | X10: COCHES GUAYADOS | Y10: 6730000 | Z10: =+(Y10*100)/Y21 -> 7.1988449 | AE10: BONIFICACION | AF10: 0 | AG10: =+(AF10*100)/$AF$18 -> #DIV/0! | AL10: INSTALADA TRAMO RIEL | AM10: 0 | AN10: =+(AM10*100)/$AM$18 -> #DIV/0! | AT10: COCHE ROCA | AU10: 0 | AV10: =+(AU10*100)/$AM$18 -> #DIV/0! | BB10: COCHE ROCA | BC10: 0 | BD10: =+(BC10*100)/$AM$18 -> #DIV/0! | BI10: METRO DE roca | BJ10: 0 | BK10: =+(BJ10*100)/BJ22 -> #DIV/0! | BP10: METRO DE roca | BQ10: 0 | BR10: =+(BQ10*100)/BQ22 -> #DIV/0! | BW10: METRO DE roca | BX10: 0 | BY10: =+(BX10*100)/BX22 -> #DIV/0!
B11: LIMPIEZA DE ESCALERAS | C11: =+'[44]CONSOLIDADO LABOR'!B561 -> 117331 | D11: =+(C11*100)/$C$17 -> 0.085605265 | G11: INSTALADA DE TRAMO RIEL | H11: =+'[44]CONSOLIDADO LABOR'!B597+'[44]CONSOLIDADO LABOR'!B617 -> 1263850 | I11: =+(H11*100)/$H$18 -> 0.94203658 | L11: TOLVEROS | M11: 4672087 | N11: 3.1402672 | R11: TOLVEROS | S11: 2567987 | T11: =+(S11*100)/S22 -> 1.6794261 | X11: LIMPIEZA DE ESCALERAS | Y11: 0 | AE11: INSTALADA TRAMO RIEL | AF11: 0 | AG11: =+(AF11*100)/$AF$18 -> #DIV/0! | AL11: BONIFICACION | AM11: 0 | AN11: =+(AM11*100)/$AM$18 -> #DIV/0! | AT11: limpieza de escaleras | AU11: 0 | AV11: =+(AU11*100)/AU21 -> #DIV/0! | BB11: limpieza de escaleras | BC11: 0 | BD11: =+(BC11*100)/BC21 -> #DIV/0! | BI11: COCHE ROCA | BJ11: 0 | BK11: =+(BJ11*100)/$AM$18 -> #DIV/0! | BP11: COCHE ROCA | BQ11: 0 | BR11: =+(BQ11*100)/BQ22 -> #DIV/0! | BW11: COCHE ROCA | BX11: 0 | BY11: =+(BX11*100)/BX22 -> #DIV/0!
B12: LIMPIEZA DE POZO | C12: 0 | D12: =+(C12*100)/$C$17 -> 0 | G12: LIMPIEZA DE ESCALERAS | H12: =+'[44]CONSOLIDADO LABOR'!B621 -> 219978 | I12: =+(H12*100)/$H$18 -> 0.16396512 | L12: coches guayados | M12: 7930500 | N12: 5.3303565 | R12: coches guayados | S12: 7364000 | T12: =+(S12*100)/S22 -> 4.8159487 | X12: CANASTA | Y12: 326400 | AE12: LIMPIEZA DE ESCALERAS | AF12: 0 | AG12: =+(AF12*100)/$AF$18 -> #DIV/0! | AL12: LIMPIEZA DE ESCALERAS | AM12: 0 | AN12: =+(AM12*100)/$AM$18 -> #DIV/0! | AT12: coches guayados | AU12: 0 | AV12: =+(AU12*100)/AU21 -> #DIV/0! | BB12: coches guayados | BC12: 0 | BD12: =+(BC12*100)/BC21 -> #DIV/0! | BI12: limpieza de escaleras | BJ12: 0 | BK12: =+(BJ12*100)/BJ22 -> #DIV/0! | BP12: TOLVEROS | BQ12: 0 | BR12: =+(BQ12*100)/BQ22 -> #DIV/0! | BW12: TOLVEROS | BX12: 0 | BY12: =+(BX12*100)/BX22 -> #DIV/0!
L13: DOMINICALES | M13: 13306878 | N13: 8.9440014 | R13: DOMINICALES | S13: 12633452 | T13: =+(S13*100)/S22 -> 8.2620936 | X13: DOMINICALES | Y13: 15000000 | Z13: =+(Y13*100)/Y21 -> 16.044974 | AE13: OTROS TURNOS | AF13: 0 | AG13: =+(AF13*100)/$AF$18 -> #DIV/0! | AL13: OTROS TURNOS | AM13: =+'CONSOLIDADO LABOR A LABOR'!I744+'CONSOLIDADO LABOR A LABOR'!I763 -> 0 | AN13: =+(AM13*100)/$AM$18 -> #DIV/0! | AT13: metro despate | AU13: 0 | AV13: =+(AU13*100)/$AM$18 -> #DIV/0! | BB13: metro despate | BC13: 0 | BD13: =+(BC13*100)/$AM$18 -> #DIV/0! | BI13: coches guayados | BJ13: 0 | BK13: =+(BJ13*100)/BJ22 -> #DIV/0! | BP13: coches guayados | BQ13: 0 | BR13: =+(BQ13*100)/BQ22 -> #DIV/0! | BW13: coches guayados | BX13: 0 | BY13: =+(BX13*100)/BX22 -> #DIV/0!
L14: MALACATEROS | M14: 4024420 | N14: 2.7049484 | R14: MALACATEROS | S14: 5603349.6 | T14: =+(S14*100)/S22 -> 3.664509 | X14: ALIMENTACION | Y14: 15487750 | Z14: =+(Y14*100)/Y21 -> 16.566703 | AE14: TURNO BOMBEO | AF14: 0 | AG14: =+(AF14*100)/$AF$18 -> #DIV/0! | AL14: TURNO BOMBEO | AM14: 0 | AN14: =+(AM14*100)/$AM$18 -> #DIV/0! | AT14: ARCO DE ACERO | AU14: 0 | AV14: =+(AU14*100)/$AM$18 -> #DIV/0! | BB14: ARCO DE ACERO | BC14: 0 | BD14: =+(BC14*100)/$AM$18 -> #DIV/0! | BI14: metro despate | BJ14: 0 | BK14: =+(BJ14*100)/$AM$18 -> #DIV/0! | BP14: DOMINICALES | BQ14: 0 | BR14: =+(BQ14*100)/$AM$18 -> #DIV/0! | BW14: DOMINICALES | BX14: 0 | BY14: =+(BX14*100)/$AM$18 -> #DIV/0!
L15: PATIEROS | M15: 3641067 | N15: 2.4472839 | R15: PATIEROS | S15: 3731711 | T15: =+(S15*100)/S22 -> 2.4404846 | X15: TOLVEROS | Y15: 2799334 | Z15: =+(Y15*100)/Y21 -> 2.9943494 | AT15: MALACATEROS | AU15: 0 | AV15: =+(AU15*100)/AU21 -> #DIV/0! | BB15: MALACATEROS | BC15: 0 | BD15: =+(BC15*100)/BC21 -> #DIV/0! | BI15: ARCO DE ACERO | BJ15: 0 | BK15: =+(BJ15*100)/$AM$18 -> #DIV/0! | BP15: ARCO DE ACERO | BQ15: 0 | BR15: =+(BQ15*100)/BQ22 -> #DIV/0! | BW15: ARCO DE ACERO | BX15: 0 | BY15: =+(BX15*100)/BX22 -> #DIV/0!
L16: SOLDADORES | M16: 2872000 | N16: 1.930368 | R16: SOLDADORES | S16: 2872000 | T16: =+(S16*100)/S22 -> 1.8782462 | X16: MALACATEROS | Y16: 5917314.5 | Z16: =+(Y16*100)/Y21 -> 6.3295437 | AT16: PATIEROS | AU16: 0 | AV16: =+(AU16*100)/AU21 -> #DIV/0! | BB16: PATIEROS | BC16: 0 | BD16: =+(BC16*100)/BC21 -> #DIV/0! | BI16: MALACATEROS | BJ16: 0 | BK16: =+(BJ16*100)/BJ22 -> #DIV/0! | BP16: MALACATEROS | BQ16: 0 | BR16: =+(BQ16*100)/BQ22 -> #DIV/0! | BW16: MALACATEROS | BX16: 0 | BY16: =+(BX16*100)/BX22 -> #DIV/0!
B17: TOTAL MES | C17: =+SUM(C2:C16) -> 137060495 | D17: =+SUM(D2:D16) -> 100 | L17: PAJARITA | M17: 2419653.9 | N17: 1.626331 | R17: PAJARITA | S17: 2303889.7 | T17: =+(S17*100)/S22 -> 1.5067103 | X17: PATIEROS | Y17: 3794195.5 | Z17: =+(Y17*100)/Y21 -> 4.0585178 | AT17: SOLDADORES | AU17: 0 | AV17: =+(AU17*100)/AU21 -> #DIV/0! | BB17: SOLDADORES | BC17: 0 | BD17: =+(BC17*100)/BC21 -> #DIV/0! | BI17: PATIEROS | BJ17: 0 | BK17: =+(BJ17*100)/BJ22 -> #DIV/0! | BP17: PATIEROS | BQ17: 0 | BR17: =+(BQ17*100)/BQ22 -> #DIV/0! | BW17: PATIEROS | BX17: 0 | BY17: =+(BX17*100)/BX22 -> #DIV/0!
G18: TOTAL MES | H18: =+SUM(H2:H17) -> 1.3416146e+08 | I18: =+SUM(I2:I17) -> 100 | L18: OTROS(TURNOS) | M18: 0 | N18: 0 | R18: OTROS(TURNOS) | T18: =+(S18*100)/S22 -> 0 | X18: SOLDADORES | Y18: 2353887 | Z18: =+(Y18*100)/Y21 -> 2.5178703 | AE18: TOTAL MES | AF18: =+SUM(AF2:AF16) -> 0 | AG18: =+SUM(AG2:AG16) -> #DIV/0! | AL18: TOTAL MES | AM18: =+SUM(AM2:AM16) -> 0 | AN18: =+SUM(AN2:AN16) -> #DIV/0! | AT18: PAJARITA | AU18: 0 | AV18: =+(AU18*100)/AU21 -> #DIV/0! | BB18: PAJARITA | BC18: 0 | BD18: =+(BC18*100)/BC21 -> #DIV/0! | BI18: SOLDADORES | BJ18: 0 | BK18: =+(BJ18*100)/BJ22 -> #DIV/0! | BP18: SOLDADORES | BQ18: 0 | BR18: =+(BQ18*100)/BQ22 -> #DIV/0! | BW18: SOLDADORES | BX18: 0 | BY18: =+(BX18*100)/BX22 -> #DIV/0!
L19: LIMPIEZA DE ESCALERAS | M19: 0 | N19: 0 | R19: LIMPIEZA DE ESCALERAS | S19: 198000 | T19: =+(S19*100)/S22 -> 0.12948912 | X19: PAJARITA | Y19: 2846897.7 | Z19: =+(Y19*100)/Y21 -> 3.0452266 | AT19: OTROS(TURNOS) | AU19: 0 | AV19: =+(AU19*100)/$AM$18 -> #DIV/0! | BB19: OTROS(TURNOS) | BC19: 0 | BD19: =+(BC19*100)/$AM$18 -> #DIV/0! | BI19: PAJARITA | BJ19: 0 | BK19: =+(BJ19*100)/BJ22 -> #DIV/0! | BP19: PAJARITA | BQ19: 0 | BR19: =+(BQ19*100)/BQ22 -> #DIV/0! | BW19: PAJARITA | BX19: 0 | BY19: =+(BX19*100)/BX22 -> #DIV/0!
L20: INSTALADA TRAMO RIEL | M20: 0 | N20: 0 | R20: INSTALADA TRAMO RIEL | T20: =+(S20*100)/S22 -> 0 | X20: OTROS(TURNOS) | Z20: =+(Y20*100)/Y21 -> 0 | AT20: BONIFICACION | AU20: 0 | AV20: =+(AU20*100)/AU21 -> #DIV/0! | BB20: BONIFICACION | BC20: 0 | BD20: =+(BC20*100)/BC21 -> #DIV/0! | BI20: OTROS(TURNOS) | BJ20: 0 | BK20: =+(BJ20*100)/$AM$18 -> #DIV/0! | BP20: OTROS(TURNOS) | BQ20: =+'[45]CONSOLIDADO LABOR'!I897+'[45]CONSOLIDADO LABOR'!I917 -> 0 | BR20: =+(BQ20*100)/BQ22 -> #DIV/0! | BW20: OTROS(TURNOS) | BX20: 0 | BY20: =+(BX20*100)/BX22 -> #DIV/0!
L21: CANASTA | M21: 260300 | N21: =+(M21*100)/M22 -> 0.17495641 | R21: CANASTA | S21: 410600 | T21: =+(S21*100)/S22 -> 0.26852642 | X21: TOTAL MES | Y21: =+SUM(Y2:Y12) -> 93487221 | Z21: =+SUM(Z2:Z12) -> 99.650861 | AT21: TOTAL MES | AU21: 0 | AV21: =+SUM(AV2:AV20) -> #DIV/0! | BB21: TOTAL MES | BC21: 0 | BD21: =+SUM(BD2:BD20) -> #DIV/0! | BI21: BONIFICACION | BJ21: 0 | BK21: =+(BJ21*100)/BJ22 -> #DIV/0! | BP21: BONIFICACION | BQ21: =+'[45]CONSOLIDADO LABOR'!B938+'[45]CONSOLIDADO LABOR'!B958 -> 0 | BR21: =+(BQ21*100)/BQ22 -> #DIV/0! | BW21: BONIFICACION | BX21: =+'[45]CONSOLIDADO LABOR'!I938+'[45]CONSOLIDADO LABOR'!I958 -> 0 | BY21: =+(BX21*100)/BX22 -> #DIV/0!
L22: TOTAL MES | M22: =SUM(M2:M21) -> 1.4877992e+08 | N22: =SUM(N2:N21) -> 100 | R22: TOTAL MES | S22: =+SUM(S2:S21) -> 1.529086e+08 | T22: =+SUM(T2:T21) -> 100 | BI22: TOTAL MES | BJ22: =+SUM(BJ2:BJ21) -> 0 | BK22: =+SUM(BK2:BK21) -> #DIV/0! | BP22: TOTAL MES | BQ22: =+SUM(BQ2:BQ21) -> 0 | BR22: =+SUM(BR2:BR21) -> #DIV/0! | BW22: TOTAL MES | BX22: =+SUM(BX2:BX21) -> 0 | BY22: =+SUM(BY2:BY21) -> #DIV/0!
AT25: TOTAL MES | AU25: =+SUM(AU2:AU23) -> 0 | AV25: =+SUM(AV2:AV23) -> #DIV/0!
A44: MES | B44: COSTOS LABORES | C44: TONELADAS
A45: ENERO | B45: =+C17 -> 137060495 | C45: 1433.12
A46: FEBRERO | B46: =+H18 -> 1.3416146e+08 | C46: 1994
A47: MARZO | B47: =+M22 -> 1.4877992e+08 | C47: 1929
A48: ABRIL | B48: =+S18 -> 0 | C48: 1841
A49: MAYO | B49: =+S18 -> 0 | C49: 2466
A50: JUNIO | B50: =+AF18 -> 0 | C50: 2030 | AG50: =+XFD50 -> 0
A51: JULIO | B51: =+AM18 -> 0 | C51: 2001
A52: AGOSTO | B52: 0 | C52: 0
A53: SEPTIEMBRE | B53: 0 | C53: 0
A54: OCTUBRE | B54: 0 | C54: 0
A55: NOVIEMBRE | B55: 0 | C55: 0
A56: DICIEMBRE | B56: 0 | C56: 0
A58: precio tonelada 2025
A59: mes | B59: $ | C59: TONELADAS
A60: ENERO | B60: =+(C17/C60)/100 -> 802.93202 | C60: 1707
A61: FEBRERO | B61: =+(H18/C61)/100 -> 672.82576 | C61: 1994
...

Sheet ENERO 2026
C13: COSTOS NOMINA 2026
C15: PRODUCCION | D15: PRECIO VTA | E15: INGRESOS TOTALES | F15: TOTAL PERSONAL
C16: =+'PRODUC ACUMULADA'!B5 -> 1698.66 | D16: 290000 | E16: =+C16*D16 -> 492611400 | F16: 71
B18: NOMINA | K18: SEGURIDAD SOCIAL
B19: ITEM | C19: TOTAL | D19: % | E19: COSTO POR TONELADA | F19: TOTAL OPERATIVOS | G19: TOTAL ADMINISTRATIVOS | H19: TOTAL ALTA GERENCIA | K19: ITEM | L19: TOTAL | M19: % | N19: COSTO POR TONELADA | O19: TOTAL PERSONAL | P19: TOTAL OPERATIVOS | Q19: TOTAL ALTA GERENCIA
B20: NOMINA OPERATIVA BAJO TIERRA | C20: =+'[52]2026 OPERATIVA'!$E$22 -> 1.0886674e+08 | D20: =+C20*100%/C25 -> 0.62478423 | E20: =+C20/C16 -> 64089.779 | F20: =+F16-G21-G22-G23-H24 -> 57 | K20: SEG SOCIAL OPERATIVA BAJO TIERRA | L20: =+O20*457363 -> 26069691 | M20: =+L20*100%/L25 -> 0.67751412 | N20: =+L20/C16 -> 15347.21 | O20: =+F20 -> 57
B21: ADMINISTRADORES OPERATIVOS | C21: =+'[53]ADMINISTRATIVA RRHH'!$F$24 -> 12363141 | D21: =+C21*100%/C25 -> 0.070951837 | E21: =+C21/C16 -> 7278.1728 | G21: 3 | K21: SEG SOCIAL ADMINISTRADORES OPERATIVOS | L21: =+P21*457363 -> 1372089 | M21: =+L21*100%/L25 -> 0.035658638 | N21: =+L21/C16 -> 807.74787 | P21: 3
B22: PERSONAL ADTIVO MANTENIMIENTO | C22: =+'[53]ADMINISTRATIVA RRHH'!$F$31 -> 3318380.3 | D22: =+C22*100%/C25 -> 0.019044123 | E22: =+C22/C16 -> 1953.5283 | G22: 1 | K22: SEG SOCIAL PERSONAL ADTIVO MANTENIMIENTO | L22: =+P22*457363 -> 457363 | M22: =+L22*100%/L25 -> 0.011886213 | N22: =+L22/C16 -> 269.24929 | P22: 1
B23: PERSONAL ADMINISTRATIVO | C23: =+'[53]ADMINISTRATIVA RRHH'!$F$37 -> 28117260 | D23: =+C23*100%/C25 -> 0.16136444 | E23: =+C23/C16 -> 16552.612 | G23: 8 | K23: SEG SOCIAL PERSONAL ADMINISTRATIVO | L23: =+P23*457363 -> 3658904 | M23: =+L23*100%/L25 -> 0.0950897 | N23: =+L23/C16 -> 2153.9943 | P23: 8
B24: ALTA GERENCIA | C24: =+'[53]ADMINISTRATIVA RRHH'!$F$42 -> 21581422 | D24: =+C24*100%/C25 -> 0.12385538 | E24: =+C24/C16 -> 12704.968 | H24: 2 | K24: ALTA GERENCIA | L24: 6920400 | M24: =+L24*100%/L25 -> 0.17985133 | N24: =+L24/C16 -> 4074.0348 | Q24: 2
B25: COSTO TONELADA | C25: =SUM(C20:C24) -> 1.7424695e+08 | D25: =SUM(D20:D24) -> 1 | E25: =SUM(E20:E24) -> 102579.06 | K25: COSTO TONELADA | L25: =SUM(L20:L24) -> 38478447 | M25: =SUM(M20:M24) -> 1 | N25: =SUM(N20:N24) -> 22652.236
E26: =+G25/(340000-H26) -> 0
B52: PRESTACIONES SOCIALES
B53: ITEM | C53: TOTAL | D53: % | E53: COSTO POR TONELADA | F53: TOTAL OPERATIVOS | G53: TOTAL ADMINISTRATIVOS | H53: TOTAL ALTA GERENCIA
B54: PRESTACIONES SOCIALES OPERATIVA BAJO TIERRA | C54: 24059257 | D54: =+C54*100%/C59 -> 0.75269456 | E54: =+C54/C16 -> 14163.668 | F54: =+F20 -> 57
B55: PRESTACIONES SOCIALES ADMINISTRADORES OPERATIVOS | C55: 1146647 | D55: =+C55*100%/C59 -> 0.035872885 | E55: =+C55/C16 -> 675.03032 | G55: =+G21 -> 3
B56: PRESTACIONES SOCIALES PERSONAL ADTIVO MANTENIMIENTO | C56: 282216 | D56: =+C56*100%/C59 -> 0.0088291359 | E56: =+C56/C16 -> 166.14037 | G56: =+G22 -> 1
B57: PRESTACIONES SOCIALES PERSONAL ADMINISTRATIVO | C57: 1764912 | D57: =+C57*100%/C59 -> 0.055215324 | E57: =+C57/C16 -> 1039.0025 | G57: =+G23 -> 8
B58: PRESTACIONES SOCIALES ALTA GERENCIA | C58: 4711138 | D58: =+C58*100%/C59 -> 0.14738809 | E58: =+C58/C16 -> 2773.4438 | H58: =+H24 -> 2
B59: COSTO TONELADA | C59: =SUM(C54:C58) -> 31964170 | D59: =SUM(D54:D58) -> 1 | E59: =SUM(E54:E58) -> 18817.285
C85: PRODUCCION | D85: PRECIO VTA | E85: INGRESOS TOTALES | F85: TOTAL PERSONAL
C86: =+C16 -> 1698.66 | D86: 290000 | E86: =+C86*D86 -> 492611400 | F86: 84
B89: TOTALES MES ENERO
B90: NOMINA MES DE ENERO | C90: =+C25 -> 1.7424695e+08 | D90: =+C90/C93 -> 0.71211434
B91: PRESTACIONES SOCIALES | C91: =+C59 -> 31964170 | D91: =+C91/C93 -> 0.13063152
B92: SEGURIDAD SOCIAL | C92: =+L25 -> 38478447 | D92: =+C92/C93 -> 0.15725414
B93: TOTALES | C93: =SUM(C90:C92) -> 2.4468956e+08 | D93: =SUM(D90:D92) -> 1

Sheet FEBRERO 2026
C13: COSTOS NOMINA 2026
C15: PRODUCCION | D15: PRECIO VTA | E15: INGRESOS TOTALES | F15: TOTAL PERSONAL
C16: =+'PRODUC ACUMULADA'!B6 -> 1830.15 | D16: 290000 | E16: =+C16*D16 -> 530743500 | F16: 75
B18: NOMINA | K18: SEGURIDAD SOCIAL
B19: ITEM | C19: TOTAL | D19: % | E19: COSTO POR TONELADA | F19: TOTAL OPERATIVOS | G19: TOTAL ADMINISTRATIVOS | H19: TOTAL ALTA GERENCIA | K19: ITEM | L19: TOTAL | M19: % | N19: COSTO POR TONELADA | O19: TOTAL OPERATIVOS | P19: TOTAL ADMONOSTRATIVOS | Q19: TOTAL ALTA GERENCIA
B20: NOMINA OPERATIVA BAJO TIERRA | C20: =+'RESUMEN 2026'!H18 -> 1.3416146e+08 | D20: =+C20*100%/C25 -> 0.67496622 | E20: =+C20/C16 -> 73306.263 | F20: =+F16-G21-G22-G23-H24 -> 61 | K20: SEG SOCIAL OPERATIVA BAJO TIERRA | L20: =+O20*478132.87 -> 29166105 | M20: =+L20*100%/L25 -> 0.69735166 | N20: =+L20/C16 -> 15936.456 | O20: =+F20 -> 61
B21: ADMINISTRADORES OPERATIVOS | C21: =+'[54]ADMINISTRATIVA RRHH'!$F$26 -> 11080141 | D21: =+C21*100%/C25 -> 0.055744183 | E21: =+C21/C16 -> 6054.2256 | G21: 3 | K21: SEG SOCIAL ADMINISTRADORES OPERATIVOS | L21: =+P21*478132.87 -> 1434398.6 | M21: =+L21*100%/L25 -> 0.034295983 | N21: =+L21/C16 -> 783.76013 | P21: =+G21 -> 3
B22: PERSONAL ADTIVO MANTENIMIENTO | C22: =+'[54]ADMINISTRATIVA RRHH'!$F$33 -> 4977570.5 | D22: =+C22*100%/C25 -> 0.025042154 | E22: =+C22/C16 -> 2719.7609 | G22: 1 | K22: SEG SOCIAL PERSONAL ADTIVO MANTENIMIENTO | L22: =+P22*478132.87 -> 478132.87 | M22: =+L22*100%/L25 -> 0.011431994 | N22: =+L22/C16 -> 261.25338 | P22: =+G22 -> 1
B23: PERSONAL ADMINISTRATIVO | C23: =+'[54]ADMINISTRATIVA RRHH'!$F$39 -> 26967072 | D23: =+C23*100%/C25 -> 0.13567133 | E23: =+C23/C16 -> 14734.897 | G23: 8 | K23: SEG SOCIAL PERSONAL ADMINISTRATIVO | L23: =+P23*478132.87 -> 3825063 | M23: =+L23*100%/L25 -> 0.091455955 | N23: =+L23/C16 -> 2090.027 | P23: =+G23 -> 8
B24: ALTA GERENCIA | C24: =+'[54]ADMINISTRATIVA RRHH'!$F$44 -> 21581422 | D24: =+C24*100%/C25 -> 0.10857612 | E24: =+C24/C16 -> 11792.16 | H24: 2 | K24: ALTA GERENCIA | L24: =+'ENERO 2026'!L24 -> 6920400 | M24: =+L24*100%/L25 -> 0.16546441 | N24: =+L24/C16 -> 3781.3294 | Q24: =+H24 -> 2
B25: COSTO TONELADA | C25: =SUM(C20:C24) -> 1.9876766e+08 | D25: =SUM(D20:D24) -> 1 | E25: =SUM(E20:E24) -> 108607.31 | K25: COSTO TONELADA | L25: =SUM(L20:L24) -> 41824100 | M25: =SUM(M20:M24) -> 1 | N25: =SUM(N20:N24) -> 22852.826
E26: =+G25/(340000-H26) -> 0
B52: PRESTACIONES SOCIALES
B53: ITEM | C53: TOTAL | D53: % | E53: COSTO POR TONELADA | F53: TOTAL OPERATIVOS | G53: TOTAL ADMINISTRATIVOS | H53: TOTAL ALTA GERENCIA
B54: PRESTACIONES SOCIALES OPERATIVA BAJO TIERRA | C54: =+[55]COSTOS!$AH$72 -> 19773245 | D54: =+C54*100%/C59 -> 0.67638696 | E54: =+C54/C16 -> 10804.166 | F54: =+F20 -> 61
B55: PRESTACIONES SOCIALES ADMINISTRADORES OPERATIVOS | C55: =+[55]COSTOS!$AH$115 -> 1146646.7 | D55: =+C55*100%/C59 -> 0.03922355 | E55: =+C55/C16 -> 626.53153 | G55: =+G21 -> 3
B56: PRESTACIONES SOCIALES PERSONAL ADTIVO MANTENIMIENTO | C56: =+[55]COSTOS!$AH$105 -> 382215.56 | D56: =+C56*100%/C59 -> 0.013074517 | E56: =+C56/C16 -> 208.84384 | G56: =+G22 -> 1
B57: PRESTACIONES SOCIALES PERSONAL ADMINISTRATIVO | C57: =+[55]COSTOS!$AH$84 -> 3220382.9 | D57: =+C57*100%/C59 -> 0.11016022 | E57: =+C57/C16 -> 1759.6279 | G57: =+G23 -> 8
B58: PRESTACIONES SOCIALES ALTA GERENCIA | C58: =+[55]COSTOS!$AH$125 -> 4711138.1 | D58: =+C58*100%/C59 -> 0.16115475 | E58: =+C58/C16 -> 2574.1814 | H58: =+H24 -> 2
B59: COSTO TONELADA | C59: =SUM(C54:C58) -> 29233628 | D59: =SUM(D54:D58) -> 1 | E59: =SUM(E54:E58) -> 15973.351
C87: PRODUCCION | D87: PRECIO VTA | E87: INGRESOS TOTALES | F87: TOTAL PERSONAL
C88: =+C16 -> 1830.15 | D88: =+D16 -> 290000 | E88: =+C88*D88 -> 530743500 | F88: =+F16 -> 75
B91: TOTALES MES FEBRERO
B92: NOMINA MES DE FEBRERO | C92: =+C25 -> 1.9876766e+08 | D92: =+C92/C95 -> 0.73665292
B93: PRESTACIONES SOCIALES | C93: =+C59 -> 29233628 | D93: =+C93/C95 -> 0.10834276
B94: SEGURIDAD SOCIAL | C94: =+L25 -> 41824100 | D94: =+C94/C95 -> 0.15500431
B95: TOTALES | C95: =SUM(C92:C94) -> 2.6982539e+08 | D95: =SUM(D92:D94) -> 1

Sheet MARZO 2026
C13: COSTOS NOMINA 2026
C15: PRODUCCION | D15: PRECIO VTA | E15: INGRESOS TOTALES | F15: TOTAL PERSONAL
C16: =+'PRODUC ACUMULADA'!B7 -> 1898.77 | D16: 290000 | E16: =+C16*D16 -> 550643300 | F16: 86
B18: NOMINA | K18: SEGURIDAD SOCIAL
B19: ITEM | C19: TOTAL | D19: % | E19: COSTO POR TONELADA | F19: TOTAL OPERATIVOS | G19: TOTAL ADMINISTRATIVOS | H19: TOTAL ALTA GERENCIA | K19: ITEM | L19: TOTAL | M19: % | N19: COSTO POR TONELADA | O19: TOTAL PERSONAL | P19: TOTAL OPERATIVOS | Q19: TOTAL ALTA GERENCIA
B20: NOMINA OPERATIVA BAJO TIERRA | C20: =+'RESUMEN 2026'!M22 -> 1.4877992e+08 | D20: =+C20*100%/C25 -> 0.69606719 | E20: =+C20/C16 -> 78355.945 | F20: =+F16-G21-G22-G23-H24 -> 71 | K20: SEG SOCIAL OPERATIVA BAJO TIERRA | L20: =+O20*463092.85 -> 32879592 | M20: =+L20*100%/L25 -> 0.71784959 | N20: =+L20/C16 -> 17316.259 | O20: =+F20 -> 71
B21: ADMINISTRADORES OPERATIVOS | C21: =+'[56]ADMINISTRATIVA RRHH'!$F$28 -> 11055141 | D21: =+C21*100%/C25 -> 0.051721503 | E21: =+C21/C16 -> 5822.2644 | G21: 3 | K21: SEG SOCIAL ADMINISTRADORES OPERATIVOS | L21: =+P21*463092.85 -> 1389278.5 | M21: =+L21*100%/L25 -> 0.030331673 | N21: =+L21/C16 -> 731.6729 | P21: 3
B22: PERSONAL ADTIVO MANTENIMIENTO | C22: =+'[56]ADMINISTRATIVA RRHH'!$F$36 -> 4396061.5 | D22: =+C22*100%/C25 -> 0.020566984 | E22: =+C22/C16 -> 2315.2154 | G22: 2 | K22: SEG SOCIAL PERSONAL ADTIVO MANTENIMIENTO | L22: =+P22*463092.85 -> 926185.7 | M22: =+L22*100%/L25 -> 0.020221115 | N22: =+L22/C16 -> 487.78193 | P22: 2
B23: PERSONAL ADMINISTRATIVO | C23: =+'[56]ADMINISTRATIVA RRHH'!$F$42 -> 27931072 | D23: =+C23*100%/C25 -> 0.13067559 | E23: =+C23/C16 -> 14710.087 | G23: 8 | K23: SEG SOCIAL PERSONAL ADMINISTRATIVO | L23: =+P23*463092.85 -> 3704742.8 | M23: =+L23*100%/L25 -> 0.08088446 | N23: =+L23/C16 -> 1951.1277 | P23: 8
B24: ALTA GERENCIA | C24: =+'[56]ADMINISTRATIVA RRHH'!$F$47 -> 21581422 | D24: =+C24*100%/C25 -> 0.10096873 | E24: =+C24/C16 -> 11366.001 | H24: 2 | K24: ALTA GERENCIA | L24: 6903100 | M24: =+L24*100%/L25 -> 0.15071317 | N24: =+L24/C16 -> 3635.5641 | Q24: 2
B25: COSTO TONELADA | C25: =SUM(C20:C24) -> 2.1374361e+08 | D25: =SUM(D20:D24) -> 1 | E25: =SUM(E20:E24) -> 112569.51 | K25: COSTO TONELADA | L25: =SUM(L20:L24) -> 45802899 | M25: =SUM(M20:M24) -> 1 | N25: =SUM(N20:N24) -> 24122.405
E26: =+G25/(340000-H26) -> 0
B52: PRESTACIONES SOCIALES
B53: ITEM | C53: TOTAL | D53: % | E53: COSTO POR TONELADA | F53: TOTAL OPERATIVOS | G53: TOTAL ADMINISTRATIVOS | H53: TOTAL ALTA GERENCIA
B54: PRESTACIONES SOCIALES OPERATIVA BAJO TIERRA | C54: =+[57]COSTOS!$AH$80 -> 20476100 | D54: =+C54*100%/C59 -> 0.6664302 | E54: =+C54/C16 -> 10783.876 | F54: =+F20 -> 71
B55: PRESTACIONES SOCIALES ADMINISTRADORES OPERATIVOS | C55: =+[57]COSTOS!$AH$142 -> 1146646.7 | D55: =+C55*100%/C59 -> 0.037319606 | E55: =+C55/C16 -> 603.88919 | G55: 3
B56: PRESTACIONES SOCIALES PERSONAL ADTIVO MANTENIMIENTO | C56: =+[57]COSTOS!$AH$126 -> 598804.48 | D56: =+C56*100%/C59 -> 0.019489131 | E56: =+C56/C16 -> 315.36441 | G56: 2
B57: PRESTACIONES SOCIALES PERSONAL ADMINISTRATIVO | C57: =+[57]COSTOS!$AH$95 -> 3792358.8 | D57: =+C57*100%/C59 -> 0.1234289 | E57: =+C57/C16 -> 1997.2713 | G57: 8
B58: PRESTACIONES SOCIALES ALTA GERENCIA | C58: =+[57]COSTOS!$AH$108 -> 4711138.1 | D58: =+C58*100%/C59 -> 0.15333216 | E58: =+C58/C16 -> 2481.1526 | H58: 2
B59: COSTO TONELADA | C59: =SUM(C54:C58) -> 30725048 | D59: =SUM(D54:D58) -> 1 | E59: =SUM(E54:E58) -> 16181.553
C88: PRODUCCION | D88: PRECIO VTA | E88: INGRESOS TOTALES | F88: TOTAL PERSONAL
C89: =+C16 -> 1898.77 | D89: =+D16 -> 290000 | E89: =+C89*D89 -> 550643300 | F89: =+F16 -> 86
B92: TOTALES MES MARZO
B93: NOMINA MES DE MARZO | C93: =+C25 -> 2.1374361e+08 | D93: =+C93/C96 -> 0.73635741
B94: PRESTACIONES SOCIALES | C94: =+C59 -> 30725048 | D94: =+C94/C96 -> 0.10584932
B95: SEGURIDAD SOCIAL | C95: =+L25 -> 45802899 | D95: =+C95/C96 -> 0.15779327
B96: TOTALES | C96: =SUM(C93:C95) -> 2.9027156e+08 | D96: =SUM(D93:D95) -> 1

Sheet ABRIL 2026
C13: COSTOS NOMINA 2026
C15: PRODUCCION | D15: PRECIO VTA | E15: INGRESOS TOTALES | F15: TOTAL PERSONAL
C16: =+'PRODUC ACUMULADA'!B8 -> 1800.91 | D16: 290000 | E16: =+C16*D16 -> 522263900 | F16: 84
B18: NOMINA | K18: SEGURIDAD SOCIAL
B19: ITEM | C19: TOTAL | D19: % | E19: COSTO POR TONELADA | F19: TOTAL OPERATIVOS | G19: TOTAL ADMINISTRATIVOS | H19: TOTAL ALTA GERENCIA | K19: ITEM | L19: TOTAL | M19: % | N19: COSTO POR TONELADA | O19: TOTAL PERSONAL | P19: TOTAL OPERATIVOS | Q19: TOTAL ALTA GERENCIA
B20: NOMINA OPERATIVA BAJO TIERRA | C20: =+'RESUMEN 2026'!S22 -> 1.529086e+08 | D20: =+C20*100%/C25 -> 0.72745108 | E20: =+C20/C16 -> 84906.3 | F20: =+F16-G21-G22-G23-H24 -> 69 | K20: SEG SOCIAL OPERATIVA BAJO TIERRA | L20: =+O20*503419 -> 34735911 | M20: =+L20*100%/L25 -> 0.72090947 | N20: =+L20/C16 -> 19287.977 | O20: =+F20 -> 69
B21: ADMINISTRADORES OPERATIVOS | C21: =+'[58]ADMINISTRATIVA RRHH'!$C$24 -> 12040240 | D21: =+C21*100%/C25 -> 0.057280525 | E21: =+C21/C16 -> 6685.642 | G21: 3 | K21: SEG SOCIAL ADMINISTRADORES OPERATIVOS | L21: =+P21*503419 -> 1510257 | M21: =+L21*100%/L25 -> 0.03134389 | N21: =+L21/C16 -> 838.6077 | P21: 3
B22: PERSONAL ADTIVO MANTENIMIENTO | C22: =+'[58]ADMINISTRATIVA RRHH'!$C$31 -> 4138742.3 | D22: =+C22*100%/C25 -> 0.019689752 | E22: =+C22/C16 -> 2298.1395 | G22: 2 | K22: SEG SOCIAL PERSONAL ADTIVO MANTENIMIENTO | L22: =+P22*503419 -> 1006838 | M22: =+L22*100%/L25 -> 0.020895927 | N22: =+L22/C16 -> 559.0718 | P22: 2
B23: PERSONAL ADMINISTRATIVO | C23: =+'[58]ADMINISTRATIVA RRHH'!$C$38 -> 21255290 | D23: =+C23*100%/C25 -> 0.10112043 | E23: =+C23/C16 -> 11802.528 | G23: 8 | K23: SEG SOCIAL PERSONAL ADMINISTRATIVO | L23: =+P23*503419 -> 4027352 | M23: =+L23*100%/L25 -> 0.083583706 | N23: =+L23/C16 -> 2236.2872 | P23: 8
B24: ALTA GERENCIA | C24: =+'[58]ADMINISTRATIVA RRHH'!$C$44 -> 19854908 | D24: =+C24*100%/C25 -> 0.094458217 | E24: =+C24/C16 -> 11024.931 | H24: 2 | K24: ALTA GERENCIA | L24: 6903100 | M24: =+L24*100%/L25 -> 0.14326701 | N24: =+L24/C16 -> 3833.1177 | Q24: 2
B25: COSTO TONELADA | C25: =SUM(C20:C24) -> 2.1019778e+08 | D25: =SUM(D20:D24) -> 1 | E25: =SUM(E20:E24) -> 116717.54 | K25: COSTO TONELADA | L25: =SUM(L20:L24) -> 48183458 | M25: =SUM(M20:M24) -> 1 | N25: =SUM(N20:N24) -> 26755.062
E26: =+G25/(340000-H26) -> 0
Q31: =+P23+P22+P21+O20 -> 82
B52: PRESTACIONES SOCIALES
B53: ITEM | C53: TOTAL | D53: % | E53: COSTO POR TONELADA | F53: TOTAL OPERATIVOS | G53: TOTAL ADMINISTRATIVOS | H53: TOTAL ALTA GERENCIA
B54: PRESTACIONES SOCIALES OPERATIVA BAJO TIERRA | C54: =+[59]COSTOS!$AH$81 -> 22754567 | D54: =+C54*100%/C59 -> 0.69528479 | E54: =+C54/C16 -> 12635.039 | F54: =+F20 -> 69
B55: PRESTACIONES SOCIALES ADMINISTRADORES OPERATIVOS | C55: =+[59]COSTOS!$AH$120 -> 1146646.7 | D55: =+C55*100%/C59 -> 0.035036746 | E55: =+C55/C16 -> 636.70404 | G55: 3
B56: PRESTACIONES SOCIALES PERSONAL ADTIVO MANTENIMIENTO | C56: =+[59]COSTOS!$AH$105 -> 586063.86 | D56: =+C56*100%/C59 -> 0.01790767 | E56: =+C56/C16 -> 325.42651 | G56: 2
B57: PRESTACIONES SOCIALES PERSONAL ADMINISTRATIVO | C57: =+[59]COSTOS!$AH$94 -> 3528558.4 | D57: =+C57*100%/C59 -> 0.10781804 | E57: =+C57/C16 -> 1959.3197 | G57: 8
B58: PRESTACIONES SOCIALES ALTA GERENCIA | C58: =+[59]COSTOS!$AH$129 -> 4711138.1 | D58: =+C58*100%/C59 -> 0.14395275 | E58: =+C58/C16 -> 2615.9764 | H58: 2
B59: COSTO TONELADA | C59: =SUM(C54:C58) -> 32726974 | D59: =SUM(D54:D58) -> 1 | E59: =SUM(E54:E58) -> 18172.465
C87: PRODUCCION | D87: PRECIO VTA | E87: INGRESOS TOTALES | F87: TOTAL PERSONAL
C88: =+C16 -> 1800.91 | D88: =+D16 -> 290000 | E88: =+C88*D88 -> 522263900 | F88: =+F16 -> 84
B91: TOTALES MES ABRIL
B92: NOMINA MES DE ABRIL | C92: =+C25 -> 2.1019778e+08 | D92: =+C92/C95 -> 0.72206064
B93: PRESTACIONES SOCIALES | C93: =+C59 -> 32726974 | D93: =+C93/C95 -> 0.11242202
B94: SEGURIDAD SOCIAL | C94: =+L25 -> 48183458 | D94: =+C94/C95 -> 0.16551734
B95: TOTALES | C95: =SUM(C92:C94) -> 2.9110822e+08 | D95: =SUM(D92:D94) -> 1

Sheet MAYO 2026
C13: COSTOS NOMINA 2026
C15: PRODUCCION | D15: PRECIO VTA | E15: INGRESOS TOTALES | F15: TOTAL PERSONAL
C16: =+'PRODUC ACUMULADA'!B9 -> 1964.11 | D16: 290000 | E16: =+C16*D16 -> 5.695919e+08 | F16: 82
B18: NOMINA | K18: SEGURIDAD SOCIAL
B19: ITEM | C19: TOTAL | D19: % | E19: COSTO POR TONELADA | F19: TOTAL OPERATIVOS | G19: TOTAL ADMINISTRATIVOS | H19: TOTAL ALTA GERENCIA | K19: ITEM | L19: TOTAL | M19: % | N19: COSTO POR TONELADA | O19: TOTAL PERSONAL | P19: TOTAL OPERATIVOS | Q19: TOTAL ALTA GERENCIA
B20: NOMINA OPERATIVA BAJO TIERRA | C20: =+'RESUMEN 2026'!Y21 -> 93487221 | D20: =+C20*100%/C25 -> 0.59450018 | E20: =+C20/C16 -> 47597.752 | F20: =+F16-G21-G22-G23-H24 -> 67 | K20: SEG SOCIAL OPERATIVA BAJO TIERRA | L20: =+O20*511273.75 -> 34255341 | M20: =+L20*100%/L25 -> 0.71603375 | N20: =+L20/C16 -> 17440.643 | O20: =+F20 -> 67
B21: ADMINISTRADORES OPERATIVOS | C21: =+'[60]ADMINISTRATIVA RRHH'!$F$31 -> 11615141 | D21: =+C21*100%/C25 -> 0.073862538 | E21: =+C21/C16 -> 5913.6917 | G21: 3 | K21: SEG SOCIAL ADMINISTRADORES OPERATIVOS | L21: =+P21*511273.75 -> 1533821.2 | M21: =+L21*100%/L25 -> 0.032061213 | N21: =+L21/C16 -> 780.92431 | P21: 3
B22: PERSONAL ADTIVO MANTENIMIENTO | C22: =+'[60]ADMINISTRATIVA RRHH'!$F$39 -> 4070378.8 | D22: =+C22*100%/C25 -> 0.02588419 | E22: =+C22/C16 -> 2072.3782 | G22: 2 | K22: SEG SOCIAL PERSONAL ADTIVO MANTENIMIENTO | L22: =+P22*511273.75 -> 1022547.5 | M22: =+L22*100%/L25 -> 0.021374142 | N22: =+L22/C16 -> 520.61621 | P22: 2
B23: PERSONAL ADMINISTRATIVO | C23: =+'[60]ADMINISTRATIVA RRHH'!$F$45 -> 26499315 | D23: =+C23*100%/C25 -> 0.16851338 | E23: =+C23/C16 -> 13491.767 | G23: 8 | K23: SEG SOCIAL PERSONAL ADMINISTRATIVO | L23: =+P23*511273.75 -> 4090190 | M23: =+L23*100%/L25 -> 0.085496568 | N23: =+L23/C16 -> 2082.4648 | P23: 8
B24: ALTA GERENCIA | C24: =+'[60]ADMINISTRATIVA RRHH'!$F$50 -> 21581422 | D24: =+C24*100%/C25 -> 0.13723971 | E24: =+C24/C16 -> 10987.889 | H24: 2 | K24: ALTA GERENCIA | L24: 6938500 | M24: =+L24*100%/L25 -> 0.14503432 | N24: =+L24/C16 -> 3532.6433 | Q24: 2
B25: COSTO TONELADA | C25: =SUM(C20:C24) -> 1.5725348e+08 | D25: =SUM(D20:D24) -> 1 | E25: =SUM(E20:E24) -> 80063.478 | K25: COSTO TONELADA | L25: =SUM(L20:L24) -> 47840400 | M25: =SUM(M20:M24) -> 1 | N25: =SUM(N20:N24) -> 24357.292
E26: =+G25/(340000-H26) -> 0
P29: =+O20+13 -> 80
B52: PRESTACIONES SOCIALES
B53: ITEM | C53: TOTAL | D53: % | E53: COSTO POR TONELADA | F53: TOTAL OPERATIVOS | G53: TOTAL ADMINISTRATIVOS | H53: TOTAL ALTA GERENCIA
B54: PRESTACIONES SOCIALES OPERATIVA BAJO TIERRA | C54: =+[61]COSTOS!$AH$77 -> 23014474 | D54: =+C54*100%/C59 -> 0.69109124 | E54: =+C54/C16 -> 11717.508 | F54: =+F20 -> 67
B55: PRESTACIONES SOCIALES ADMINISTRADORES OPERATIVOS | C55: =+[61]COSTOS!$AH$106 -> 1146646.7 | D55: =+C55*100%/C59 -> 0.034432135 | E55: =+C55/C16 -> 583.79962 | G55: 3
B56: PRESTACIONES SOCIALES PERSONAL ADTIVO MANTENIMIENTO | C56: =+[61]COSTOS!$AH$96 -> 764431.12 | D56: =+C56*100%/C59 -> 0.022954756 | E56: =+C56/C16 -> 389.19975 | G56: 2
B57: PRESTACIONES SOCIALES PERSONAL ADMINISTRATIVO | C57: =+[61]COSTOS!$AH$90 -> 3664953.6 | D57: =+C57*100%/C59 -> 0.11005324 | E57: =+C57/C16 -> 1865.9615 | G57: 8
B58: PRESTACIONES SOCIALES ALTA GERENCIA | C58: =+[61]COSTOS!$AH$120 -> 4711138.1 | D58: =+C58*100%/C59 -> 0.14146864 | E58: =+C58/C16 -> 2398.6121 | H58: 2
B59: COSTO TONELADA | C59: =SUM(C54:C58) -> 33301644 | D59: =SUM(D54:D58) -> 1 | E59: =SUM(E54:E58) -> 16955.081
C88: PRODUCCION | D88: PRECIO VTA | E88: INGRESOS TOTALES | F88: TOTAL PERSONAL
C89: =+C16 -> 1964.11 | D89: =+D16 -> 290000 | E89: =+C89*D89 -> 5.695919e+08 | F89: 84
B92: TOTALES MES MAYO
B93: NOMINA MES DE MAYO | C93: =+C25 -> 1.5725348e+08 | D93: =+C93/C96 -> 0.65963268
B94: PRESTACIONES SOCIALES | C94: =+C59 -> 33301644 | D94: =+C94/C96 -> 0.13969073
B95: SEGURIDAD SOCIAL | C95: =+L25 -> 47840400 | D95: =+C95/C96 -> 0.20067659
B96: TOTALES | C96: =SUM(C93:C95) -> 2.3839552e+08 | D96: =SUM(D93:D95) -> 1

Sheet JUNIO 2026
C13: COSTOS NOMINA 2025
C15: PRODUCCION | D15: PRECIO VTA | E15: INGRESOS TOTALES | F15: TOTAL PERSONAL
C16: =+'PRODUC ACUMULADA'!B10 -> 0 | D16: 293653 | E16: =+C16*D16 -> 0 | F16: 79
B18: NOMINA | K18: SEGURIDAD SOCIAL
B19: ITEM | C19: TOTAL | D19: % | E19: COSTO POR TONELADA | F19: TOTAL OPERATIVOS | G19: TOTAL ADMINISTRATIVOS | H19: TOTAL ALTA GERENCIA | K19: ITEM | L19: TOTAL | M19: % | N19: COSTO POR TONELADA | O19: TOTAL PERSONAL | P19: TOTAL OPERATIVOS | Q19: TOTAL ALTA GERENCIA
B20: NOMINA OPERATIVA BAJO TIERRA | C20: =+'RESUMEN 2026'!AF18 -> 0 | D20: =+C20*100%/C25 -> #DIV/0! | E20: =+C20/C16 -> #DIV/0! | F20: =+F16-G21-G22-G23-H24 -> 65 | K20: SEG SOCIAL OPERATIVA BAJO TIERRA | L20: 0 | M20: =+L20*100%/L25 -> #DIV/0! | N20: =+L20/C16 -> #DIV/0! | O20: =+F20 -> 65
B21: ADMINISTRADORES OPERATIVOS | C21: 0 | D21: =+C21*100%/C25 -> #DIV/0! | E21: =+C21/C16 -> #DIV/0! | G21: 3 | K21: SEG SOCIAL ADMINISTRADORES OPERATIVOS | L21: 0 | M21: =+L21*100%/L25 -> #DIV/0! | N21: =+L21/C16 -> #DIV/0! | P21: 3
B22: PERSONAL ADTIVO MANTENIMIENTO | C22: 0 | D22: =+C22*100%/C25 -> #DIV/0! | E22: =+C22/C16 -> #DIV/0! | G22: 2 | K22: SEG SOCIAL PERSONAL ADTIVO MANTENIMIENTO | L22: 0 | M22: =+L22*100%/L25 -> #DIV/0! | N22: =+L22/C16 -> #DIV/0! | P22: 2
B23: PERSONAL ADMINISTRATIVO | C23: 0 | D23: =+C23*100%/C25 -> #DIV/0! | E23: =+C23/C16 -> #DIV/0! | G23: 7 | K23: SEG SOCIAL PERSONAL ADMINISTRATIVO | L23: 0 | M23: =+L23*100%/L25 -> #DIV/0! | N23: =+L23/C16 -> #DIV/0! | P23: 7
B24: ALTA GERENCIA | C24: 0 | D24: =+C24*100%/C25 -> #DIV/0! | E24: =+C24/C16 -> #DIV/0! | H24: 2 | K24: ALTA GERENCIA | L24: 0 | M24: =+L24*100%/L25 -> #DIV/0! | N24: =+L24/C16 -> #DIV/0! | Q24: 2
B25: COSTO TONELADA | C25: =SUM(C20:C24) -> 0 | D25: =SUM(D20:D24) -> #DIV/0! | E25: =SUM(E20:E24) -> #DIV/0! | K25: COSTO TONELADA | L25: =SUM(L20:L24) -> 0 | M25: =SUM(M20:M24) -> #DIV/0! | N25: =SUM(N20:N24) -> #DIV/0!
E26: =+G25/(340000-H26) -> 0
B52: PRESTACIONES SOCIALES
B53: ITEM | C53: TOTAL | D53: % | E53: COSTO POR TONELADA | F53: TOTAL OPERATIVOS | G53: TOTAL ADMINISTRATIVOS | H53: TOTAL ALTA GERENCIA
B54: PRESTACIONES SOCIALES OPERATIVA BAJO TIERRA | C54: 0 | D54: =+C54*100%/C59 -> #DIV/0! | E54: =+C54/C16 -> #DIV/0! | F54: =+F20 -> 65
B55: PRESTACIONES SOCIALES ADMINISTRADORES OPERATIVOS | C55: 0 | D55: =+C55*100%/C59 -> #DIV/0! | E55: =+C55/C16 -> #DIV/0! | G55: 3
B56: PRESTACIONES SOCIALES PERSONAL ADTIVO MANTENIMIENTO | C56: 0 | D56: =+C56*100%/C59 -> #DIV/0! | E56: =+C56/C16 -> #DIV/0! | G56: 2
B57: PRESTACIONES SOCIALES PERSONAL ADMINISTRATIVO | C57: 0 | D57: =+C57*100%/C59 -> #DIV/0! | E57: =+C57/C16 -> #DIV/0! | G57: 7
B58: PRESTACIONES SOCIALES ALTA GERENCIA | C58: 0 | D58: =+C58*100%/C59 -> #DIV/0! | E58: =+C58/C16 -> #DIV/0! | H58: 2
B59: COSTO TONELADA | C59: =SUM(C54:C58) -> 0 | D59: =SUM(D54:D58) -> #DIV/0! | E59: =SUM(E54:E58) -> #DIV/0!
C86: PRODUCCION | D86: PRECIO VTA | E86: INGRESOS TOTALES | F86: TOTAL PERSONAL
C87: =+C16 -> 0 | D87: =+D16 -> 293653 | E87: =+C87*D87 -> 0 | F87: =+F16 -> 79
B90: TOTALES MES JUNIO
B91: NOMINA MES DE JUNIO | C91: =+C25 -> 0 | D91: =+C91/C94 -> #DIV/0!
B92: PRESTACIONES SOCIALES | C92: =+C59 -> 0 | D92: =+C92/C94 -> #DIV/0!
B93: SEGURIDAD SOCIAL | C93: =+L25 -> 0 | D93: =+C93/C94 -> #DIV/0!
B94: TOTALES | C94: =SUM(C91:C93) -> 0 | D94: =SUM(D91:D93) -> #DIV/0!

Sheet JULIO 2026
C13: COSTOS NOMINA 2025
C15: PRODUCCION | D15: PRECIO VTA | E15: INGRESOS TOTALES | F15: TOTAL PERSONAL
C16: =+'PRODUC ACUMULADA'!B11 -> 0 | D16: 279000 | E16: =+C16*D16 -> 0 | F16: 77
B18: NOMINA | K18: SEGURIDAD SOCIAL
B19: ITEM | C19: TOTAL | D19: % | E19: COSTO POR TONELADA | F19: TOTAL OPERATIVOS | G19: TOTAL ADMINISTRATIVOS | H19: TOTAL ALTA GERENCIA | K19: ITEM | L19: TOTAL | M19: % | N19: COSTO POR TONELADA | O19: TOTAL PERSONAL | P19: TOTAL OPERATIVOS | Q19: TOTAL ALTA GERENCIA
B20: NOMINA OPERATIVA BAJO TIERRA | C20: =+'RESUMEN 2026'!AM18 -> 0 | D20: =+C20*100%/C25 -> #DIV/0! | E20: =+C20/C16 -> #DIV/0! | F20: =+F16-G21-G22-G23-H24 -> 63 | K20: SEG SOCIAL OPERATIVA BAJO TIERRA | L20: 0 | M20: =+L20*100%/L25 -> #DIV/0! | N20: =+L20/C16 -> #DIV/0! | O20: =+F20 -> 63
B21: ADMINISTRADORES OPERATIVOS | C21: 0 | D21: =+C21*100%/C25 -> #DIV/0! | E21: =+C21/C16 -> #DIV/0! | G21: 3 | K21: SEG SOCIAL ADMINISTRADORES OPERATIVOS | L21: 0 | M21: =+L21*100%/L25 -> #DIV/0! | N21: =+L21/C16 -> #DIV/0! | P21: 3
B22: PERSONAL ADTIVO MANTENIMIENTO | C22: 0 | D22: =+C22*100%/C25 -> #DIV/0! | E22: =+C22/C16 -> #DIV/0! | G22: 2 | K22: SEG SOCIAL PERSONAL ADTIVO MANTENIMIENTO | L22: 0 | M22: =+L22*100%/L25 -> #DIV/0! | N22: =+L22/C16 -> #DIV/0! | P22: 2
B23: PERSONAL ADMINISTRATIVO | C23: 0 | D23: =+C23*100%/C25 -> #DIV/0! | E23: =+C23/C16 -> #DIV/0! | G23: 7 | K23: SEG SOCIAL PERSONAL ADMINISTRATIVO | L23: 0 | M23: =+L23*100%/L25 -> #DIV/0! | N23: =+L23/C16 -> #DIV/0! | P23: 7
B24: ALTA GERENCIA | C24: 0 | D24: =+C24*100%/C25 -> #DIV/0! | E24: =+C24/C16 -> #DIV/0! | H24: 2 | K24: ALTA GERENCIA | L24: 0 | M24: =+L24*100%/L25 -> #DIV/0! | N24: =+L24/C16 -> #DIV/0! | Q24: 2
B25: COSTO TONELADA | C25: =SUM(C20:C24) -> 0 | D25: =SUM(D20:D24) -> #DIV/0! | E25: =SUM(E20:E24) -> #DIV/0! | K25: COSTO TONELADA | L25: =SUM(L20:L24) -> 0 | M25: =SUM(M20:M24) -> #DIV/0! | N25: =SUM(N20:N24) -> #DIV/0!
E26: =+G25/(340000-H26) -> 0
P29: =+O20+P21+P22+P23 -> 75
B52: PRESTACIONES SOCIALES
B53: ITEM | C53: TOTAL | D53: % | E53: COSTO POR TONELADA | F53: TOTAL OPERATIVOS | G53: TOTAL ADMINISTRATIVOS | H53: TOTAL ALTA GERENCIA
B54: PRESTACIONES SOCIALES OPERATIVA BAJO TIERRA | C54: 0 | D54: =+C54*100%/C59 -> #DIV/0! | E54: =+C54/C16 -> #DIV/0! | F54: 69
B55: PRESTACIONES SOCIALES ADMINISTRADORES OPERATIVOS | C55: 0 | D55: =+C55*100%/C59 -> #DIV/0! | E55: =+C55/C16 -> #DIV/0! | G55: 3
B56: PRESTACIONES SOCIALES PERSONAL ADTIVO MANTENIMIENTO | C56: 0 | D56: =+C56*100%/C59 -> #DIV/0! | E56: =+C56/C16 -> #DIV/0! | G56: 2
B57: PRESTACIONES SOCIALES PERSONAL ADMINISTRATIVO | C57: 0 | D57: =+C57*100%/C59 -> #DIV/0! | E57: =+C57/C16 -> #DIV/0! | G57: 7
B58: PRESTACIONES SOCIALES ALTA GERENCIA | C58: 0 | D58: =+C58*100%/C59 -> #DIV/0! | E58: =+C58/C16 -> #DIV/0! | H58: 2
B59: COSTO TONELADA | C59: =SUM(C54:C58) -> 0 | D59: =SUM(D54:D58) -> #DIV/0! | E59: =SUM(E54:E58) -> #DIV/0!
C88: PRODUCCION | D88: PRECIO VTA | E88: INGRESOS TOTALES | F88: TOTAL PERSONAL
C89: =+C16 -> 0 | D89: =+D16 -> 279000 | E89: =+C89*D89 -> 0 | F89: =+F16 -> 77
B92: TOTALES MES JULIO
B93: NOMINA MES DE JULIO | C93: =+C25 -> 0 | D93: =+C93/C96 -> #DIV/0!
B94: PRESTACIONES SOCIALES | C94: =+C59 -> 0 | D94: =+C94/C96 -> #DIV/0!
B95: SEGURIDAD SOCIAL | C95: =+L25 -> 0 | D95: =+C95/C96 -> #DIV/0!
B96: TOTALES | C96: =SUM(C93:C95) -> 0 | D96: =SUM(D93:D95) -> #DIV/0!

Sheet AGOSTO 2026
C13: COSTOS NOMINA 2025
C15: PRODUCCION | D15: PRECIO VTA | E15: INGRESOS TOTALES | F15: TOTAL PERSONAL
C16: =+'PRODUC ACUMULADA'!B12 -> 0 | D16: 275000 | E16: =+C16*D16 -> 0 | F16: 86
B18: NOMINA | K18: SEGURIDAD SOCIAL
B19: ITEM | C19: TOTAL | D19: % | E19: COSTO POR TONELADA | F19: TOTAL OPERATIVOS | G19: TOTAL ADMINISTRATIVOS | H19: TOTAL ALTA GERENCIA | K19: ITEM | L19: TOTAL | M19: % | N19: COSTO POR TONELADA | O19: TOTAL PERSONAL | P19: TOTAL OPERATIVOS | Q19: TOTAL ALTA GERENCIA
B20: NOMINA OPERATIVA BAJO TIERRA | C20: =+'RESUMEN 2026'!AU21 -> 0 | D20: =+C20*100%/C25 -> #DIV/0! | E20: =+C20/C16 -> #DIV/0! | F20: =+F16-G21-G22-G23 -> 75 | K20: SEG SOCIAL OPERATIVA BAJO TIERRA | L20: 0 | M20: =+L20*100%/L25 -> #DIV/0! | N20: =+L20/C16 -> #DIV/0! | O20: =+F20 -> 75
B21: ADMINISTRADORES OPERATIVOS | C21: 0 | D21: =+C21*100%/C25 -> #DIV/0! | E21: =+C21/C16 -> #DIV/0! | G21: 3 | K21: SEG SOCIAL ADMINISTRADORES OPERATIVOS | L21: 0 | M21: =+L21*100%/L25 -> #DIV/0! | N21: =+L21/C16 -> #DIV/0! | P21: 3
B22: PERSONAL ADTIVO MANTENIMIENTO | C22: 0 | D22: =+C22*100%/C25 -> #DIV/0! | E22: =+C22/C16 -> #DIV/0! | G22: 2 | K22: SEG SOCIAL PERSONAL ADTIVO MANTENIMIENTO | L22: 0 | M22: =+L22*100%/L25 -> #DIV/0! | N22: =+L22/C16 -> #DIV/0! | P22: 2
B23: PERSONAL ADMINISTRATIVO | C23: 0 | D23: =+C23*100%/C25 -> #DIV/0! | E23: =+C23/C16 -> #DIV/0! | G23: 6 | K23: SEG SOCIAL PERSONAL ADMINISTRATIVO | L23: 0 | M23: =+L23*100%/L25 -> #DIV/0! | N23: =+L23/C16 -> #DIV/0! | P23: 6
B24: ALTA GERENCIA | C24: 0 | D24: =+C24*100%/C25 -> #DIV/0! | E24: =+C24/C16 -> #DIV/0! | H24: 2 | K24: ALTA GERENCIA | L24: 0 | M24: =+L24*100%/L25 -> #DIV/0! | N24: =+L24/C16 -> #DIV/0! | Q24: 2
B25: COSTO TONELADA | C25: =SUM(C20:C24) -> 0 | D25: =SUM(D20:D24) -> #DIV/0! | E25: =SUM(E20:E24) -> #DIV/0! | K25: COSTO TONELADA | L25: =SUM(L20:L24) -> 0 | M25: =SUM(M20:M24) -> #DIV/0! | N25: =SUM(N20:N24) -> #DIV/0!
E26: =+G25/(340000-H26) -> 0
Q32: =+O20+P21+P22+P23 -> 86
B52: PRESTACIONES SOCIALES
B53: ITEM | C53: TOTAL | D53: % | E53: COSTO POR TONELADA | F53: TOTAL OPERATIVOS | G53: TOTAL ADMINISTRATIVOS | H53: TOTAL ALTA GERENCIA
B54: PRESTACIONES SOCIALES OPERATIVA BAJO TIERRA | C54: 0 | D54: =+C54*100%/C59 -> #DIV/0! | E54: =+C54/C16 -> #DIV/0! | F54: =+F20 -> 75
B55: PRESTACIONES SOCIALES ADMINISTRADORES OPERATIVOS | C55: 0 | D55: =+C55*100%/C59 -> #DIV/0! | E55: =+C55/C16 -> #DIV/0! | G55: 3
B56: PRESTACIONES SOCIALES PERSONAL ADTIVO MANTENIMIENTO | C56: 0 | D56: =+C56*100%/C59 -> #DIV/0! | E56: =+C56/C16 -> #DIV/0! | G56: 2
B57: PRESTACIONES SOCIALES PERSONAL ADMINISTRATIVO | C57: 0 | D57: =+C57*100%/C59 -> #DIV/0! | E57: =+C57/C16 -> #DIV/0! | G57: 6
B58: PRESTACIONES SOCIALES ALTA GERENCIA | C58: 0 | D58: =+C58*100%/C59 -> #DIV/0! | E58: =+C58/C16 -> #DIV/0! | H58: 2
B59: COSTO TONELADA | C59: =SUM(C54:C58) -> 0 | D59: =SUM(D54:D58) -> #DIV/0! | E59: =SUM(E54:E58) -> #DIV/0!
C88: PRODUCCION | D88: PRECIO VTA | E88: INGRESOS TOTALES | F88: TOTAL PERSONAL
C89: =+C16 -> 0 | D89: =+D16 -> 275000 | E89: =+C89*D89 -> 0 | F89: =+F16 -> 86
B92: TOTALES MES AGOSTO
B93: NOMINA MES DE AGOSTO | C93: =+C25 -> 0 | D93: =+C93/C96 -> #DIV/0!
B94: PRESTACIONES SOCIALES | C94: =+C59 -> 0 | D94: =+C94/C96 -> #DIV/0!
B95: SEGURIDAD SOCIAL | C95: =+L25 -> 0 | D95: =+C95/C96 -> #DIV/0!
B96: TOTALES | C96: =SUM(C93:C95) -> 0 | D96: =SUM(D93:D95) -> #DIV/0!

Sheet SEPTIEMBRE 2026
C13: COSTOS NOMINA 2025
C15: PRODUCCION | D15: PRECIO VTA | E15: INGRESOS TOTALES | F15: TOTAL PERSONAL
C16: =+'PRODUC ACUMULADA'!B13 -> 0 | D16: 275000 | E16: =+C16*D16 -> 0 | F16: 88
B18: NOMINA | K18: SEGURIDAD SOCIAL
B19: ITEM | C19: TOTAL | D19: % | E19: COSTO POR TONELADA | F19: TOTAL OPERATIVOS | G19: TOTAL ADMINISTRATIVOS | H19: TOTAL ALTA GERENCIA | K19: ITEM | L19: TOTAL | M19: % | N19: COSTO POR TONELADA | O19: TOTAL PERSONAL | P19: TOTAL OPERATIVOS | Q19: TOTAL ALTA GERENCIA
B20: NOMINA OPERATIVA BAJO TIERRA | C20: =+'RESUMEN 2026'!AM18 -> 0 | D20: =+C20*100%/C25 -> #DIV/0! | E20: =+C20/C16 -> #DIV/0! | F20: =+F16-G21-G22-G23-H24 -> 75 | K20: SEG SOCIAL OPERATIVA BAJO TIERRA | L20: 0 | M20: =+L20*100%/L25 -> #DIV/0! | N20: =+L20/C16 -> #DIV/0! | O20: =+F20 -> 75
B21: ADMINISTRADORES OPERATIVOS | C21: 0 | D21: =+C21*100%/C25 -> #DIV/0! | E21: =+C21/C16 -> #DIV/0! | G21: 3 | K21: SEG SOCIAL ADMINISTRADORES OPERATIVOS | L21: 0 | M21: =+L21*100%/L25 -> #DIV/0! | N21: =+L21/C16 -> #DIV/0! | P21: 3
B22: PERSONAL ADTIVO MANTENIMIENTO | C22: 0 | D22: =+C22*100%/C25 -> #DIV/0! | E22: =+C22/C16 -> #DIV/0! | G22: 2 | K22: SEG SOCIAL PERSONAL ADTIVO MANTENIMIENTO | L22: 0 | M22: =+L22*100%/L25 -> #DIV/0! | N22: =+L22/C16 -> #DIV/0! | P22: 2
B23: PERSONAL ADMINISTRATIVO | C23: 0 | D23: =+C23*100%/C25 -> #DIV/0! | E23: =+C23/C16 -> #DIV/0! | G23: 6 | K23: SEG SOCIAL PERSONAL ADMINISTRATIVO | L23: 0 | M23: =+L23*100%/L25 -> #DIV/0! | N23: =+L23/C16 -> #DIV/0! | P23: 6
B24: ALTA GERENCIA | C24: 0 | D24: =+C24*100%/C25 -> #DIV/0! | E24: =+C24/C16 -> #DIV/0! | H24: 2 | K24: ALTA GERENCIA | L24: 0 | M24: =+L24*100%/L25 -> #DIV/0! | N24: =+L24/C16 -> #DIV/0! | Q24: 2
B25: COSTO TONELADA | C25: =SUM(C20:C24) -> 0 | D25: =SUM(D20:D24) -> #DIV/0! | E25: =SUM(E20:E24) -> #DIV/0! | K25: COSTO TONELADA | L25: =SUM(L20:L24) -> 0 | M25: =SUM(M20:M24) -> #DIV/0! | N25: =SUM(N20:N24) -> #DIV/0!
E26: =+G25/(340000-H26) -> 0
P29: =+O20+P21+P22+P23 -> 86
B52: PRESTACIONES SOCIALES
B53: ITEM | C53: TOTAL | D53: % | E53: COSTO POR TONELADA | F53: TOTAL OPERATIVOS | G53: TOTAL ADMINISTRATIVOS | H53: TOTAL ALTA GERENCIA
B54: PRESTACIONES SOCIALES OPERATIVA BAJO TIERRA | C54: 0 | D54: =+C54*100%/C59 -> #DIV/0! | E54: =+C54/C16 -> #DIV/0! | F54: =+F20 -> 75
B55: PRESTACIONES SOCIALES ADMINISTRADORES OPERATIVOS | C55: 0 | D55: =+C55*100%/C59 -> #DIV/0! | E55: =+C55/C16 -> #DIV/0! | G55: 3
B56: PRESTACIONES SOCIALES PERSONAL ADTIVO MANTENIMIENTO | C56: 0 | D56: =+C56*100%/C59 -> #DIV/0! | E56: =+C56/C16 -> #DIV/0! | G56: 2
B57: PRESTACIONES SOCIALES PERSONAL ADMINISTRATIVO | C57: 0 | D57: =+C57*100%/C59 -> #DIV/0! | E57: =+C57/C16 -> #DIV/0! | G57: 6
B58: PRESTACIONES SOCIALES ALTA GERENCIA | C58: 0 | D58: =+C58*100%/C59 -> #DIV/0! | E58: =+C58/C16 -> #DIV/0! | H58: 2
B59: COSTO TONELADA | C59: =SUM(C54:C58) -> 0 | D59: =SUM(D54:D58) -> #DIV/0! | E59: =SUM(E54:E58) -> #DIV/0!
C88: PRODUCCION | D88: PRECIO VTA | E88: INGRESOS TOTALES | F88: TOTAL PERSONAL
C89: =+C16 -> 0 | D89: =+D16 -> 275000 | E89: =+C89*D89 -> 0 | F89: =+F16 -> 88
B92: TOTALES MES SEPTIEMBRE
B93: NOMINA MES DE JULIO | C93: =+C25 -> 0 | D93: =+C93/C96 -> #DIV/0!
B94: PRESTACIONES SOCIALES | C94: =+C59 -> 0 | D94: =+C94/C96 -> #DIV/0!
B95: SEGURIDAD SOCIAL | C95: =+L25 -> 0 | D95: =+C95/C96 -> #DIV/0!
B96: TOTALES | C96: =SUM(C93:C95) -> 0 | D96: =SUM(D93:D95) -> #DIV/0!

Sheet OCTUBRE 2026
C13: COSTOS NOMINA 2025
C15: PRODUCCION | D15: PRECIO VTA | E15: INGRESOS TOTALES | F15: TOTAL PERSONAL
C16: =+'PRODUC ACUMULADA'!B14 -> 0 | D16: =+[62]PRODUCCION!$B$18 -> 308000 | E16: =+C16*D16 -> 0 | F16: 70
B18: NOMINA | K18: SEGURIDAD SOCIAL
