Workbook
Name ARP: '[1]Datos Básicos'!$F$9
Name AT: '[1]Datos Básicos'!$B$6
Name CAJA: '[1]Datos Básicos'!$B$11
Name Cesantia: '[1]Datos Básicos'!$B$19
Name EMPLEADOS: #REF!
Name EMPLEADOS: #REF!
Name ESAP: '[1]Datos Básicos'!$F$15
Name ExtraDiurna: '[1]Datos Básicos'!#REF!
Name ExtraDiurna: '[1]Datos Básicos'!#REF!
Name ExtraDiurnaDominicalFestivo: '[1]Datos Básicos'!#REF!
Name ExtraDiurnaDominicalFestivo: '[1]Datos Básicos'!#REF!
Name ExtraNocturna: '[1]Datos Básicos'!#REF!
Name ExtraNocturna: '[1]Datos Básicos'!#REF!
Name FonSol1: '[1]Datos Básicos'!$B$26
Name FonSol2: '[1]Datos Básicos'!$B$27
Name FonSol3: '[1]Datos Básicos'!$B$28
Name FonSol4: '[1]Datos Básicos'!$B$29
Name FonSol5: '[1]Datos Básicos'!$B$30
Name FonSol6: '[1]Datos Básicos'!$B$31
Name ICBF: '[1]Datos Básicos'!$B$10
Name IND: '[1]Datos Básicos'!$F$16
Name IntCesantia: '[1]Datos Básicos'!$B$22
Name OrdinariaDominicalFestivo: '[1]Datos Básicos'!#REF!
Name OrdinariaDominicalFestivo: '[1]Datos Básicos'!#REF!
Name PensionEmpleado: '[1]Datos Básicos'!$B$16
Name PensionEmpresa: '[1]Datos Básicos'!$C$16
Name Prima: '[1]Datos Básicos'!$B$20
Name RecargoNocturno: '[1]Datos Básicos'!#REF!
Name RecargoNocturno: '[1]Datos Básicos'!#REF!
Name SaludEmpleado: '[1]Datos Básicos'!$B$15
Name SaludEmpresa: '[1]Datos Básicos'!$C$15
Name SENA: '[1]Datos Básicos'!$B$9
Name SM: '[1]Datos Básicos'!$B$5
Name UVT: '[1]Datos Básicos'!$F$11
Name Vacaciones: '[1]Datos Básicos'!$B$21
Name ValorHora: [1]Calculos!$B$4

Sheet ENERO
C13: PRODUCCION 2026
C15: PRODUCCION | D15: PRECIO VTA | E15: INGRESOS TOTALES
B16: PROCUCCION | C16: 1150.22 | D16: 290000 | E16: =+C16*D16 -> 333563800
B19: ITEM | C19: TOTAL | D19: % | E19: COSTO POR TONELADA | F19: =+C16 -> 1150.22 | G19: CF | H19: CV
B20: CUOTA ACERIAS | C20: 63611017 | D20: =+C20*100%/C53 -> 0.13137304 | E20: =+C20/F19 -> 55303.348 | F20: CF | G20: =+C20 -> 63611017
B21: ENERGIA | C21: 29603230 | D21: =+C21*100%/C53 -> 0.061138253 | E21: =+C21/F19 -> 25737.016 | F21: CV | H21: =+C21 -> 29603230
B22: COMBUSTIBLE | C22: 3431124 | D22: =+C22*100%/C53 -> 0.0070861499 | E22: =+C22/F19 -> 2983.0154 | F22: CV | H22: =+C22 -> 3431124
B23: MADERA | C23: 7369000 | D23: =+C23*100%/C53 -> 0.015218873 | E23: =+C23/F19 -> 6406.6005 | F23: CV | H23: =+C23 -> 7369000
B24: NOMINA | C24: 1.6882274e+08 | D24: =+C24*100%/C53 -> 0.34866221 | E24: =+C24/F19 -> 146774.31 | F24: CV | H24: =+C24 -> 1.6882274e+08
B25: CARGA PRESTACI | C25: 70442617 | D25: =+C25*100%/C53 -> 0.14548205 | E25: =+C25/F19 -> 61242.734 | F25: CV | H25: =+C25 -> 70442617
B26: INSUMOS | C26: 23584638 | D26: =+C26*100%/C53 -> 0.048708318 | E26: =+C26/F19 -> 20504.458 | F26: CV | H26: =+C26 -> 23584638
B27: CALIBRACION | C27: 150000 | D27: =+C27*100%/C53 -> 0.00030978842 | E27: =+C27/F19 -> 130.40983 | F27: CV | H27: =+C27 -> 150000
B28: ELEMEN ASEO | C28: 166666 | D28: =+C28*100%/C53 -> 0.00034420798 | E28: =+C28/F19 -> 144.89924 | F28: CF | G28: =+C28 -> 166666
B29: DOTACION | C29: 1645000 | D29: =+C29*100%/C53 -> 0.0033973464 | E29: =+C29/F19 -> 1430.1612 | F29: CV | H29: =+C29 -> 1645000
B30: EXAMENES ING Y RETIRO | C30: 211000 | D30: =+C30*100%/C53 -> 0.00043576905 | E30: =+C30/F19 -> 183.44317 | F30: CV | H30: =+C30 -> 211000
B31: PAPELERIA | C31: 0 | D31: =+C31*100%/C53 -> 0 | E31: =+C31/F19 -> 0 | F31: CF | G31: =+C31 -> 0
B32: PEAJES | C32: 0 | D32: =+C32*100%/C53 -> 0 | E32: =+C32/F19 -> 0 | F32: CV | H32: =+C32 -> 0
B33: TRANS PASA | C33: 210000 | D33: =+C33*100%/C53 -> 0.00043370379 | E33: =+C33/F19 -> 182.57377 | F33: CV | H33: =+C33 -> 210000
B34: APORTES FEDERACION | C34: 0 | D34: =+C34*100%/C53 -> 0 | E34: =+C34/F19 -> 0 | F34: CF | G34: =+C34 -> 0 | H34: 0
B35: VIATICOS | C35: 4000000 | D35: =+C35*100%/C53 -> 0.0082610246 | E35: =+C35/F19 -> 3477.5956 | F35: CV | H35: =+C35 -> 4000000
B36: RESTAURANTE | C36: 17914000 | D36: =+C36*100%/C53 -> 0.036996999 | E36: =+C36/F19 -> 15574.412 | F36: CV | H36: =+C36 -> 17914000
B37: MANT EQUIPOS | C37: 1000000 | D37: =+C37*100%/C53 -> 0.0020652561 | E37: =+C37/F19 -> 869.3989 | F37: CF | G37: =+C37 -> 1000000 | H37: 0
B38: LEVANT TOPOGRAFICO | C38: 400000 | D38: =+C38*100%/C53 -> 0.00082610246 | E38: =+C38/F19 -> 347.75956 | F38: CF | G38: =+C38 -> 400000
B39: TRANS CARBON | C39: 34506600 | D39: =+C39*100%/C53 -> 0.071264968 | E39: =+C39/F19 -> 30000 | F39: CF | G39: =+C39 -> 34506600
B40: TELEFONO | C40: 293000 | D40: =+C40*100%/C53 -> 0.00060512005 | E40: =+C40/F19 -> 254.73388 | F40: CF | G40: =+C40 -> 293000
B41: POLIZA | C41: 1457156 | D41: =+C41*100%/C53 -> 0.0030094004 | E41: =+C41/F19 -> 1266.8498 | F41: CF | G41: =+C41 -> 1457156 | H41: 0
B42: VARIOS | C42: 0 | D42: =+C42*100%/C53 -> 0 | E42: =+C42/F19 -> 0 | F42: CV | H42: =+C42 -> 0
B43: PUBLICIDAD | C43: 0 | D43: =+C43*100%/C53 -> 0 | E43: =+C43/F19 -> 0 | F43: CV | H43: =+C43 -> 0
B44: INTERNET | C44: 537000 | D44: =+C44*100%/C53 -> 0.0011090425 | E44: =+C44/F19 -> 466.86721 | F44: CF | G44: =+C44 -> 537000
B45: ASESORES EXTERNOS | C45: 700000 | D45: =+C45*100%/C53 -> 0.0014456793 | E45: =+C45/F19 -> 608.57923 | F45: CF | G45: =+C45 -> 700000
B46: PAJARITA | C46: 16711773 | D46: =+C46*100%/C53 -> 0.034514091 | E46: =+C46/F19 -> 14529.197 | F46: CF | G46: =+C46 -> 16711773
B47: ARRIENDO | C47: 750000 | D47: =+C47*100%/C53 -> 0.0015489421 | E47: =+C47/F19 -> 652.04917 | F47: CF | G47: =+C47 -> 750000
B48: % SERVIDUMBRE | C48: 16850707 | D48: =+C48*100%/C53 -> 0.034801026 | E48: =+C48/F19 -> 14649.986 | F48: CV | H48: =+C48 -> 16850707
B49: DEPRECIACION | D49: =+C49*100%/C53 -> 0 | E49: =+C49/F19 -> 0 | F49: CF | G49: =+C49 -> 0
B50: AUTORENTA | C50: 4251213.1 | D50: =+C50*100%/C53 -> 0.008779844 | E50: =+C50/F19 -> 3696 | F50: CV | H50: =+C50 -> 4251213.1
B51: GASTOS BANCARIOS | C51: 1956000 | D51: =+C51*100%/C53 -> 0.004039641 | E51: =+C51/F19 -> 1700.5442 | F51: CF | G51: =+C51 -> 1956000 | I51: =SUM(G53:H53) -> 4.8420144e+08
B52: PAGO REGALIAS | C52: 13626958 | D52: =+C52*100%/C53 -> 0.028143158 | E52: =+C52/F19 -> 11847.262 | F52: CV | H52: =+C52 -> 13626958
C53: =SUM(C20:C52) -> 4.8420144e+08 | D53: =SUM(D20:D52) -> 1 | E53: =SUM(E20:E52) -> 420964.2 | F53: =SUM(F20:F52) -> 0 | G53: =SUM(G20:G52) -> 1.2208921e+08 | H53: =SUM(H20:H52) -> 3.6211223e+08
C54: PE = CF / (P-CVU) | D54: PE | E54: =+G53/(290000-H54) -> -4918.9905 | G54: CVU | H54: =+H53/F19 -> 314819.97

Sheet FEBRERO
C13: PRODUCCION 2026
C15: PRODUCCION | D15: PRECIO VTA | E15: INGRESOS TOTALES
B16: PRODUCCION | C16: =+'PRODUC ACUMULADA'!B6 -> 1830.15 | D16: 325000 | E16: =+C16*D16 -> 594798750
B19: ITEM | C19: TOTAL | D19: % | E19: COSTO POR TONELADA | F19: =+C16 -> 1830.15 | G19: CF | H19: CV
B20: CUOTA ACERIAS | C20: 63611017 | D20: =+C20*100%/C53 -> 0.1132511 | E20: =+C20/F19 -> 34757.27 | F20: CF | G20: =+C20 -> 63611017
B21: ENERGIA | C21: 29368280 | D21: =+C21*100%/C53 -> 0.052286386 | E21: =+C21/F19 -> 16046.925 | F21: CV | H21: =+C21 -> 29368280
B22: COMBUSTIBLE | C22: 12535782 | D22: =+C22*100%/C53 -> 0.022318322 | E22: =+C22/F19 -> 6849.5927 | F22: CV | H22: =+C22 -> 12535782
B23: MADERA | C23: 8182000 | D23: =+C23*100%/C53 -> 0.014566982 | E23: =+C23/F19 -> 4470.6718 | F23: CV | H23: =+C23 -> 8182000
B24: NOMINA | C24: 1.9876766e+08 | D24: =+C24*100%/C53 -> 0.35387985 | E24: =+C24/F19 -> 108607.31 | F24: CV | H24: =+C24 -> 1.9876766e+08
B25: CARGA PRESTACI | C25: 71057727 | D25: =+C25*100%/C53 -> 0.126509 | E25: =+C25/F19 -> 38826.177 | F25: CV | H25: =+C25 -> 71057727
B26: INSUMOS | C26: 20158111 | D26: =+C26*100%/C53 -> 0.035888883 | E26: =+C26/F19 -> 11014.458 | F26: CV | H26: =+C26 -> 20158111
B27: CALIBRACION | C27: 150000 | D27: =+C27*100%/C53 -> 0.0002670554 | E27: =+C27/F19 -> 81.960495 | F27: CV | H27: =+C27 -> 150000
B28: ELEMEN ASEO | C28: 166666 | D28: =+C28*100%/C53 -> 0.00029672704 | E28: =+C28/F19 -> 91.066852 | F28: CF | G28: =+C28 -> 166666
B29: DOTACION | C29: 3818000 | D29: =+C29*100%/C53 -> 0.0067974502 | E29: =+C29/F19 -> 2086.1678 | F29: CV | H29: =+C29 -> 3818000
B30: EXAMENES ING Y RETIRO | C30: 1818000 | D30: =+C30*100%/C53 -> 0.0032367115 | E30: =+C30/F19 -> 993.3612 | F30: CV | H30: =+C30 -> 1818000
B31: PAPELERIA | C31: 0 | D31: =+C31*100%/C53 -> 0 | E31: =+C31/F19 -> 0 | F31: CF | G31: =+C31 -> 0
B32: PEAJES | C32: 0 | D32: =+C32*100%/C53 -> 0 | E32: =+C32/F19 -> 0 | F32: CV | H32: =+C32 -> 0
B33: TRANS PASA | C33: 210000 | D33: =+C33*100%/C53 -> 0.00037387756 | E33: =+C33/F19 -> 114.74469 | F33: CV | H33: =+C33 -> 210000
B34: APORTES FEDERACION | C34: 0 | D34: =+C34*100%/C53 -> 0 | E34: =+C34/F19 -> 0 | F34: CF | G34: =+C34 -> 0 | H34: 0
B35: VIATICOS | C35: 4000000 | D35: =+C35*100%/C53 -> 0.0071214774 | E35: =+C35/F19 -> 2185.6132 | F35: CV | H35: =+C35 -> 4000000
B36: RESTAURANTE | C36: 17914000 | D36: =+C36*100%/C53 -> 0.031893537 | E36: =+C36/F19 -> 9788.2687 | F36: CV | H36: =+C36 -> 17914000
B37: MANT EQUIPOS | C37: 6008352 | D37: =+C37*100%/C53 -> 0.010697086 | E37: =+C37/F19 -> 3282.9834 | F37: CF | G37: =+C37 -> 6008352 | H37: 0
B38: LEVANT TOPOGRAFICO | C38: 400000 | D38: =+C38*100%/C53 -> 0.00071214774 | E38: =+C38/F19 -> 218.56132 | F38: CF | G38: =+C38 -> 400000
B39: TRANS CARBON | C39: 54904500 | D39: =+C39*100%/C53 -> 0.097750289 | E39: =+C39/F19 -> 30000 | F39: CF | G39: =+C39 -> 54904500
B40: TELEFONO | C40: 293000 | D40: =+C40*100%/C53 -> 0.00052164822 | E40: =+C40/F19 -> 160.09617 | F40: CF | G40: =+C40 -> 293000
B41: POLIZA | C41: 1457156 | D41: =+C41*100%/C53 -> 0.0025942759 | E41: =+C41/F19 -> 796.19485 | F41: CF | G41: =+C41 -> 1457156 | H41: 0
B42: VARIOS | C42: 0 | D42: =+C42*100%/C53 -> 0 | E42: =+C42/F19 -> 0 | F42: CV | H42: =+C42 -> 0
B43: PUBLICIDAD | C43: 0 | D43: =+C43*100%/C53 -> 0 | E43: =+C43/F19 -> 0 | F43: CV | H43: =+C43 -> 0
B44: INTERNET | C44: 537000 | D44: =+C44*100%/C53 -> 0.00095605834 | E44: =+C44/F19 -> 293.41857 | F44: CF | G44: =+C44 -> 537000
B45: ASESORES EXTERNOS | C45: 700000 | D45: =+C45*100%/C53 -> 0.0012462585 | E45: =+C45/F19 -> 382.48231 | F45: CF | G45: =+C45 -> 700000
B46: PAJARITA | C46: 16711773 | D46: =+C46*100%/C53 -> 0.029753128 | E46: =+C46/F19 -> 9131.3677 | F46: CF | G46: =+C46 -> 16711773
B47: ARRIENDO | C47: 750000 | D47: =+C47*100%/C53 -> 0.001335277 | E47: =+C47/F19 -> 409.80248 | F47: CF | G47: =+C47 -> 750000
B48: % SERVIDUMBRE | C48: 18154989 | D48: =+C48*100%/C53 -> 0.032322586 | E48: =+C48/F19 -> 9919.9459 | F48: CV | H48: =+C48 -> 18154989
B49: DEPRECIACION | D49: =+C49*100%/C53 -> 0 | E49: =+C49/F19 -> 0 | F49: CF | G49: =+C49 -> 0
B50: AUTORENTA | C50: 6368922 | D50: =+C50*100%/C53 -> 0.011339034 | E50: =+C50/F19 -> 3480 | F50: CV | H50: =+C50 -> 6368922
B51: GASTOS BANCARIOS | C51: 1956000 | D51: =+C51*100%/C53 -> 0.0034824024 | E51: =+C51/F19 -> 1068.7649 | F51: CF | G51: =+C51 -> 1956000 | I51: =SUM(G53:H53) -> 5.616812e+08
B52: PAGO REGALIAS | C52: 21682267 | D52: =+C52*100%/C53 -> 0.038602443 | E52: =+C52/F19 -> 11847.262 | F52: CV | H52: =+C52 -> 21682267
C53: =SUM(C20:C52) -> 5.616812e+08 | D53: =SUM(D20:D52) -> 1 | E53: =SUM(E20:E52) -> 306904.46 | F53: =SUM(F20:F52) -> 0 | G53: =SUM(G20:G52) -> 1.4749546e+08 | H53: =SUM(H20:H52) -> 4.1418574e+08
C54: PE = CF / (P-CVU) | D54: PE | E54: =+G53/(290000-H54) -> 2315.9232 | G54: CVU | H54: =+H53/F19 -> 226312.46

Sheet MARZO
C13: PRODUCCION 2026
C15: PRODUCCION | D15: PRECIO VTA | E15: INGRESOS TOTALES
B16: PRODUCCION | C16: =+'PRODUC ACUMULADA'!B7 -> 1898.77 | D16: 290000 | E16: =+C16*D16 -> 550643300
B19: ITEM | C19: TOTAL | D19: % | E19: COSTO POR TONELADA | F19: =+C16 -> 1898.77 | G19: CF | H19: CV
B20: CUOTA ACERIAS | C20: 63611017 | D20: =+C20*100%/C53 -> 0.10753301 | E20: =+C20/F19 -> 33501.17 | F20: CF | G20: =+C20 -> 63611017
B21: ENERGIA | C21: 38315850 | D21: =+C21*100%/C53 -> 0.06477209 | E21: =+C21/F19 -> 20179.3 | F21: CV | H21: =+C21+3000000 -> 41315850
B22: COMBUSTIBLE | C22: 4480816 | D22: =+C22*100%/C53 -> 0.0075747196 | E22: =+C22/F19 -> 2359.8519 | F22: CV | H22: =+C22 -> 4480816
B23: MADERA | C23: 10796500 | D23: =+C23*100%/C53 -> 0.018251243 | E23: =+C23/F19 -> 5686.0494 | F23: CV | H23: =+C23 -> 10796500
B24: NOMINA | C24: 2.1374361e+08 | D24: =+C24*100%/C53 -> 0.36132882 | E24: =+C24/F19 -> 112569.51 | F24: CV | H24: =+C24 -> 2.1374361e+08
B25: CARGA PRESTACI | C25: 76527947 | D25: =+C25*100%/C53 -> 0.12936879 | E25: =+C25/F19 -> 40303.958 | F25: CV | H25: =+C25 -> 76527947
B26: INSUMOS | C26: 20658931 | D26: =+C26*100%/C53 -> 0.034923462 | E26: =+C26/F19 -> 10880.165 | F26: CV | H26: =+C26 -> 20658931
B27: CALIBRACION | C27: 150000 | D27: =+C27*100%/C53 -> 0.00025357166 | E27: =+C27/F19 -> 78.99851 | F27: CV | H27: =+C27 -> 150000
B28: ELEMEN ASEO | C28: 166666 | D28: =+C28*100%/C53 -> 0.00028174516 | E28: =+C28/F19 -> 87.775771 | F28: CF | G28: =+C28 -> 166666
B29: DOTACION | C29: 7751000 | D29: =+C29*100%/C53 -> 0.013102893 | E29: =+C29/F19 -> 4082.1163 | F29: CV | H29: =+C29 -> 7751000
B30: EXAMENES ING Y RETIRO | C30: 0 | D30: =+C30*100%/C53 -> 0 | E30: =+C30/F19 -> 0 | F30: CV | H30: =+C30 -> 0
B31: PAPELERIA | C31: 0 | D31: =+C31*100%/C53 -> 0 | E31: =+C31/F19 -> 0 | F31: CF | G31: =+C31 -> 0
B32: PEAJES | C32: 0 | D32: =+C32*100%/C53 -> 0 | E32: =+C32/F19 -> 0 | F32: CV | H32: =+C32 -> 0
B33: TRANS PASA | C33: 880000 | D33: =+C33*100%/C53 -> 0.0014876204 | E33: =+C33/F19 -> 463.45792 | F33: CV | H33: =+C33 -> 880000
B34: APORTES FEDERACION | C34: 0 | D34: =+C34*100%/C53 -> 0 | E34: =+C34/F19 -> 0 | F34: CF | G34: =+C34 -> 0 | H34: 0
B35: VIATICOS | C35: 4000000 | D35: =+C35*100%/C53 -> 0.0067619108 | E35: =+C35/F19 -> 2106.6269 | F35: CV | H35: =+C35 -> 4000000
B36: RESTAURANTE | C36: 21459750 | D36: =+C36*100%/C53 -> 0.036277229 | E36: =+C36/F19 -> 11301.922 | F36: CV | H36: =+C36 -> 21459750
B37: MANT EQUIPOS | C37: 0 | D37: =+C37*100%/C53 -> 0 | E37: =+C37/F19 -> 0 | F37: CF | G37: =+C37 -> 0 | H37: 0
B38: LEVANT TOPOGRAFICO | C38: 400000 | D38: =+C38*100%/C53 -> 0.00067619108 | E38: =+C38/F19 -> 210.66269 | F38: CF | G38: =+C38 -> 400000
B39: TRANS CARBON | C39: 56963100 | D39: =+C39*100%/C53 -> 0.096294851 | E39: =+C39/F19 -> 30000 | F39: CF | G39: =+C39 -> 56963100
B40: TELEFONO | C40: 293000 | D40: =+C40*100%/C53 -> 0.00049530997 | E40: =+C40/F19 -> 154.31042 | F40: CF | G40: =+C40 -> 293000
B41: POLIZA | C41: 1457156 | D41: =+C41*100%/C53 -> 0.0024632897 | E41: =+C41/F19 -> 767.42101 | F41: CF | G41: =+C41 -> 1457156 | H41: 0
B42: VARIOS | C42: 0 | D42: =+C42*100%/C53 -> 0 | E42: =+C42/F19 -> 0 | F42: CV | H42: =+C42 -> 0
B43: PUBLICIDAD | C43: 0 | D43: =+C43*100%/C53 -> 0 | E43: =+C43/F19 -> 0 | F43: CV | H43: =+C43 -> 0
B44: INTERNET | C44: 537000 | D44: =+C44*100%/C53 -> 0.00090778653 | E44: =+C44/F19 -> 282.81466 | F44: CF | G44: =+C44 -> 537000
B45: ASESORES EXTERNOS | C45: 2000000 | D45: =+C45*100%/C53 -> 0.0033809554 | E45: =+C45/F19 -> 1053.3135 | F45: CF | G45: =+C45 -> 2000000
B46: PAJARITA | C46: 16711773 | D46: =+C46*100%/C53 -> 0.028250879 | E46: =+C46/F19 -> 8801.3675 | F46: CF | G46: =+C46 -> 16711773
B47: ARRIENDO | C47: 750000 | D47: =+C47*100%/C53 -> 0.0012678583 | E47: =+C47/F19 -> 394.99255 | F47: CF | G47: =+C47 -> 750000
B48: % SERVIDUMBRE | C48: 18835699 | D48: =+C48*100%/C53 -> 0.031841329 | E48: =+C48/F19 -> 9919.9477 | F48: CV | H48: =+C48 -> 18835699
B49: DEPRECIACION | D49: =+C49*100%/C53 -> 0 | E49: =+C49/F19 -> 0 | F49: CF | G49: =+C49 -> 0
B50: AUTORENTA | C50: 6607719.6 | D50: =+C50*100%/C53 -> 0.011170203 | E50: =+C50/F19 -> 3480 | F50: CV | H50: =+C50 -> 6607719.6
B51: GASTOS BANCARIOS | C51: 1956000 | D51: =+C51*100%/C53 -> 0.0033065744 | E51: =+C51/F19 -> 1030.1406 | F51: CF | G51: =+C51 -> 1956000 | I51: =SUM(G53:H53) -> 5.9454876e+08
B52: PAGO REGALIAS | C52: 22495226 | D52: =+C52*100%/C53 -> 0.038027678 | E52: =+C52/F19 -> 11847.262 | F52: CV | H52: =+C52 -> 22495226
C53: =SUM(C20:C52) -> 5.9154876e+08 | D53: =SUM(D20:D52) -> 1 | E53: =SUM(E20:E52) -> 311543.14 | F53: =SUM(F20:F52) -> 0 | G53: =SUM(G20:G52) -> 1.4484571e+08 | H53: =SUM(H20:H52) -> 4.4970305e+08
C54: PE = CF / (P-CVU) | D54: PE | E54: =+G53/(290000-H54) -> 2724.6683 | G54: CVU | H54: =+H53/F19 -> 236839.14

Sheet ABRIL
C13: PRODUCCION 2026
B15: PRODUCCION | C15: 0 | D15: PRODUCCION | E15: PRECIO VTA | F15: INGRESOS TOTALES
D16: =+'PRODUC ACUMULADA'!B8 -> 1800.91 | E16: 290000 | F16: =+D16*E16 -> 522263900
C18: 2026
B19: ITEM | C19: TOTAL | D19: % | E19: COSTO POR TONELADA | F19: 1840.79 | G19: CF | H19: CV
B20: CUOTA ACERIAS | C20: 63611017 | D20: =+C20*100%/C53 -> 0.1083142 | E20: =+C20/F19 -> 34556.368 | F20: CF | G20: =+C20 -> 63611017
B21: ENERGIA | C21: 36893750 | D21: =+C21*100%/C53 -> 0.062821147 | E21: =+C21/F19 -> 20042.346 | F21: CV | H21: =+C21+5000000 -> 41893750
B22: COMBUSTIBLE | C22: 4609346 | D22: =+C22*100%/C53 -> 0.0078486032 | E22: =+C22/F19 -> 2504.0043 | F22: CV | H22: =+C22 -> 4609346
B23: MADERA | C23: 10794500 | D23: =+C23*100%/C53 -> 0.018380427 | E23: =+C23/F19 -> 5864.0584 | F23: CV | H23: =+C23 -> 10794500
B24: NOMINA | C24: 2.1019778e+08 | D24: =+C24*100%/C53 -> 0.35791607 | E24: =+C24/F19 -> 114188.9 | F24: CV | H24: =+C24 -> 2.1019778e+08
B25: CARGA PRESTACI | C25: 80910432 | D25: =+C25*100%/C53 -> 0.13777093 | E25: =+C25/F19 -> 43954.189 | F25: CV | H25: =+C25 -> 80910432
B26: INSUMOS | C26: 14065477 | D26: =+C26*100%/C53 -> 0.023950111 | E26: =+C26/F19 -> 7641.0003 | F26: CV | H26: =+C26 -> 14065477
B27: CALIBRACION | C27: 150000 | D27: =+C27*100%/C53 -> 0.00025541378 | E27: =+C27/F19 -> 81.486753 | F27: CV | H27: =+C27 -> 150000
B28: ELEMEN ASEO | C28: 166666 | D28: =+C28*100%/C53 -> 0.00028379195 | E28: =+C28/F19 -> 90.540474 | F28: CF | G28: =+C28 -> 166666
B29: DOTACION | C29: 7743200 | D29: =+C29*100%/C53 -> 0.0131848 | E29: =+C29/F19 -> 4206.4548 | F29: CV | H29: =+C29 -> 7743200
B30: EXAMENES ING Y RETIRO | C30: 880000 | D30: =+C30*100%/C53 -> 0.0014984275 | E30: =+C30/F19 -> 478.05562 | F30: CV | H30: =+C30 -> 880000
B31: PAPELERIA | C31: 0 | D31: =+C31*100%/C53 -> 0 | E31: =+C31/F19 -> 0 | F31: CF | G31: =+C31 -> 0
B32: PEAJES | C32: 0 | D32: =+C32*100%/C53 -> 0 | E32: =+C32/F19 -> 0 | F32: CV | H32: =+C32 -> 0
B33: TRANS PASA | C33: 960000 | D33: =+C33*100%/C53 -> 0.0016346482 | E33: =+C33/F19 -> 521.51522 | F33: CV | H33: =+C33 -> 960000
B34: APORTES FEDERACION | C34: 0 | D34: =+C34*100%/C53 -> 0 | E34: =+C34/F19 -> 0 | F34: CF | G34: =+C34 -> 0 | H34: 0
B35: VIATICOS | C35: 4000000 | D35: =+C35*100%/C53 -> 0.0068110341 | E35: =+C35/F19 -> 2172.9801 | F35: CV | H35: =+C35 -> 4000000
B36: RESTAURANTE | C36: 20731750 | D36: =+C36*100%/C53 -> 0.035301164 | E36: =+C36/F19 -> 11262.42 | F36: CV | H36: =+C36 -> 20731750
B37: MANT EQUIPOS | C37: 0 | D37: =+C37*100%/C53 -> 0 | E37: =+C37/F19 -> 0 | F37: CF | G37: =+C37 -> 0 | H37: 0
B38: LEVANT TOPOGRAFICO | C38: 400000 | D38: =+C38*100%/C53 -> 0.00068110341 | E38: =+C38/F19 -> 217.29801 | F38: CF | G38: =+C38 -> 400000
B39: TRANS CARBON | C39: 54027300 | D39: =+C39*100%/C53 -> 0.091995445 | E39: =+C39/F19 -> 29350.062 | F39: CF | G39: =+C39 -> 54027300
B40: TELEFONO | C40: 293000 | D40: =+C40*100%/C53 -> 0.00049890825 | E40: =+C40/F19 -> 159.17079 | F40: CF | G40: =+C40 -> 293000
B41: POLIZA | C41: 1457156 | D41: =+C41*100%/C53 -> 0.0024811848 | E41: =+C41/F19 -> 791.59274 | F41: CF | G41: =+C41 -> 1457156 | H41: 0
B42: VARIOS | C42: 0 | D42: =+C42*100%/C53 -> 0 | E42: =+C42/F19 -> 0 | F42: CV | H42: =+C42 -> 0
B43: PUBLICIDAD | C43: 0 | D43: =+C43*100%/C53 -> 0 | E43: =+C43/F19 -> 0 | F43: CV | H43: =+C43 -> 0
B44: INTERNET | C44: 537000 | D44: =+C44*100%/C53 -> 0.00091438132 | E44: =+C44/F19 -> 291.72258 | F44: CF | G44: =+C44 -> 537000
B45: ASESORES EXTERNOS | C45: 700000 | D45: =+C45*100%/C53 -> 0.001191931 | E45: =+C45/F19 -> 380.27151 | F45: CF | G45: =+C45 -> 700000
B46: PAJARITA | C46: 16711773 | D46: =+C46*100%/C53 -> 0.028456113 | E46: =+C46/F19 -> 9078.5873 | F46: CF | G46: =+C46 -> 16711773
B47: ARRIENDO | C47: 750000 | D47: =+C47*100%/C53 -> 0.0012770689 | E47: =+C47/F19 -> 407.43376 | F47: CF | G47: =+C47 -> 750000
B48: % SERVIDUMBRE | C48: 17864928 | D48: =+C48*100%/C53 -> 0.030419658 | E48: =+C48/F19 -> 9705.0332 | F48: CV | H48: =+C48 -> 17864928
B49: DEPRECIACION | D49: =+C49*100%/C53 -> 0 | E49: =+C49/F19 -> 0 | F49: CF | G49: =+C49 -> 0
B50: AUTORENTA | C50: 6267166.8 | D50: =+C50*100%/C53 -> 0.010671472 | E50: =+C50/F19 -> 3404.6072 | F50: CV | H50: =+C50 -> 6267166.8
B51: GASTOS BANCARIOS | C51: 2080300 | D51: =+C51*100%/C53 -> 0.0035422485 | E51: =+C51/F19 -> 1130.1126 | F51: CF | G51: =+C51 -> 2080300
B52: PAGO REGALIAS | C52: 30479789 | D52: =+C52*100%/C53 -> 0.051899721 | E52: =+C52/F19 -> 16557.994 | F52: CV | H52: =+C52 -> 30479789
C53: =SUM(C20:C52) -> 5.8728234e+08 | D53: =SUM(D20:D52) -> 1 | E53: =SUM(E20:E52) -> 319038.2 | G53: =SUM(G20:G52) -> 1.4073421e+08 | H53: =SUM(H20:H52) -> 4.5154812e+08
C54: PE = CF / (P-CVU) | D54: PE | E54: =+G53/(290000-H54) -> 3148.5058 | G54: CVU | H54: =+H53/F19 -> 245301.27
...

Sheet MAYO
B13: PRODUCCION 2026
A15: PRODUCCION | B15: 0 | C15: PRODUCCION | D15: PRECIO VTA | E15: INGRESOS TOTALES
C16: =+'PRODUC ACUMULADA'!B9 -> 1964.11 | D16: 290000 | E16: =+C16*D16 -> 5.695919e+08
B18: 2026
A19: ITEM | B19: TOTAL | C19: % | D19: COSTO POR TONELADA | E19: =+C16 -> 1964.11 | F19: CF | G19: CV
A20: CUOTA ACERIAS | B20: 63611017 | C20: =+B20*100%/B53 -> 0.11799152 | D20: =+B20/E19 -> 32386.688 | E20: CF | F20: =+B20 -> 63611017
A21: ENERGIA | B21: 31502690 | C21: =+B21*100%/B53 -> 0.058434066 | D21: =+B21/E19 -> 16039.168 | E21: CV | G21: =+B21 -> 31502690
A22: COMBUSTIBLE | B22: 11596960 | C22: =+B22*100%/B53 -> 0.0215111 | D22: =+B22/E19 -> 5904.4351 | E22: CV | G22: =+B22 -> 11596960
A23: MADERA | B23: 9099500 | C23: =+B23*100%/B53 -> 0.016878583 | D23: =+B23/E19 -> 4632.8872 | E23: CV | G23: =+B23 -> 9099500
A24: NOMINA | B24: 1.5725348e+08 | C24: =+B24*100%/B53 -> 0.29168811 | D24: =+B24/E19 -> 80063.478 | E24: CV | G24: =+B24 -> 1.5725348e+08
A25: CARGA PRESTACI | B25: 81142044 | C25: =+B25*100%/B53 -> 0.15050967 | D25: =+B25/E19 -> 41312.372 | E25: CV | G25: =+B25 -> 81142044
A26: INSUMOS | B26: 19639124 | C26: =+B26*100%/B53 -> 0.03642844 | D26: =+B26/E19 -> 9998.9939 | E26: CV | G26: =+B26 -> 19639124
A27: CALIBRACION | B27: 0 | C27: =+B27*100%/B53 -> 0 | D27: =+B27/E19 -> 0 | E27: CV | G27: =+B27 -> 0
A28: ELEMEN ASEO | B28: 166666 | C28: =+B28*100%/B53 -> 0.00030914731 | D28: =+B28/E19 -> 84.855736 | E28: CF | F28: =+B28 -> 166666
A29: DOTACION | B29: 1095800 | C29: =+B29*100%/B53 -> 0.0020325899 | D29: =+B29/E19 -> 557.91173 | E29: CV | G29: =+B29 -> 1095800
A30: EXAMENES ING Y RETIRO | B30: 3480000 | C30: =+B30*100%/B53 -> 0.0064550217 | D30: =+B30/E19 -> 1771.7949 | E30: CV | G30: =+B30 -> 3480000
A31: PAPELERIA | B31: 0 | C31: =+B31*100%/B53 -> 0 | D31: =+B31/E19 -> 0 | E31: CF | F31: =+B31 -> 0
A32: PEAJES | B32: 0 | C32: =+B32*100%/B53 -> 0 | D32: =+B32/E19 -> 0 | E32: CV | G32: =+B32 -> 0
A33: TRANS PASA | B33: 960000 | C33: =+B33*100%/B53 -> 0.0017806956 | D33: =+B33/E19 -> 488.771 | E33: CV | G33: =+B33 -> 960000
A34: APORTES FEDERACION | B34: 0 | C34: =+B34*100%/B53 -> 0 | D34: =+B34/E19 -> 0 | E34: CF | F34: =+B34 -> 0 | G34: 0
A35: VIATICOS | B35: 4000000 | C35: =+B35*100%/B53 -> 0.0074195652 | D35: =+B35/E19 -> 2036.5458 | E35: CV | G35: =+B35 -> 4000000
A36: RESTAURANTE | B36: 23087468 | C36: =+B36*100%/B53 -> 0.042824744 | D36: =+B36/E19 -> 11754.672 | E36: CV | G36: =+B36 -> 23087468
A37: MANT EQUIPOS | B37: 0 | C37: =+B37*100%/B53 -> 0 | D37: =+B37/E19 -> 0 | E37: CF | F37: =+B37 -> 0 | G37: 0
A38: LEVANT TOPOGRAFICO | B38: 400000 | C38: =+B38*100%/B53 -> 0.00074195652 | D38: =+B38/E19 -> 203.65458 | E38: CF | F38: =+B38 -> 400000
A39: TRANS CARBON | B39: 49921100 | C39: =+B39*100%/B53 -> 0.092598214 | D39: =+B39/E19 -> 25416.652 | E39: CF | F39: =+B39 -> 49921100
A40: TELEFONO | B40: 293000 | C40: =+B40*100%/B53 -> 0.00054348315 | D40: =+B40/E19 -> 149.17698 | E40: CF | F40: =+B40 -> 293000
A41: POLIZA | B41: 1457156 | C41: =+B41*100%/B53 -> 0.002702866 | D41: =+B41/E19 -> 741.89124 | E41: CF | F41: =+B41 -> 1457156 | G41: 0
A42: VARIOS | B42: 0 | C42: =+B42*100%/B53 -> 0 | D42: =+B42/E19 -> 0 | E42: CV | G42: =+B42 -> 0
A43: PUBLICIDAD | B43: 0 | C43: =+B43*100%/B53 -> 0 | D43: =+B43/E19 -> 0 | E43: CV | G43: =+B43 -> 0
A44: INTERNET | B44: 537000 | C44: =+B44*100%/B53 -> 0.00099607663 | D44: =+B44/E19 -> 273.40628 | E44: CF | F44: =+B44 -> 537000
A45: ASESORES EXTERNOS | B45: 700000 | C45: =+B45*100%/B53 -> 0.0012984239 | D45: =+B45/E19 -> 356.39552 | E45: CF | F45: =+B45 -> 700000
A46: PAJARITA | B46: 16711773 | C46: =+B46*100%/B53 -> 0.030998522 | D46: =+B46/E19 -> 8508.5727 | E46: CF | F46: =+B46 -> 16711773
A47: ARRIENDO | B47: 750000 | C47: =+B47*100%/B53 -> 0.0013911685 | D47: =+B47/E19 -> 381.85234 | E47: CF | F47: =+B47 -> 750000
A48: % SERVIDUMBRE | B48: 19483078 | C48: =+B48*100%/B53 -> 0.036138993 | D48: =+B48/E19 -> 9919.5454 | E48: CV | G48: =+B48 -> 19483078
A49: DEPRECIACION | C49: =+B49*100%/B53 -> 0 | D49: =+B49/E19 -> 0 | E49: CF | F49: =+B49 -> 0
A50: AUTORENTA | B50: 6835102.8 | C50: =+B50*100%/B53 -> 0.012678373 | D50: =+B50/E19 -> 3480 | E50: CV | G50: =+B50 -> 6835102.8
A51: GASTOS BANCARIOS | B51: 2150300 | C51: =+B51*100%/B53 -> 0.0039885728 | D51: =+B51/E19 -> 1094.7961 | E51: CF | F51: =+B51 -> 2150300
A52: PAGO REGALIAS | B52: 33241894 | C52: =+B52*100%/B53 -> 0.0616601 | D52: =+B52/E19 -> 16924.66 | E52: CV | G52: =+B52 -> 33241894
B53: =SUM(B20:B52) -> 5.3911515e+08 | C53: =SUM(C20:C52) -> 1 | D53: =SUM(D20:D52) -> 274483.18 | F53: =SUM(F20:F52) -> 1.3669801e+08 | G53: =SUM(G20:G52) -> 4.0241714e+08
B54: PE = CF / (P-CVU) | C54: PE | D54: =+F53/(290000-G54) -> 1606.0434 | F54: CVU | G54: =+G53/E19 -> 204885.23

Sheet JUNIO
A13: PROCUCCION | B13: 0 | C13: PRODUCCION | D13: PRECIO VTA | E13: INGRESOS TOTALES
D14: 293653 | E14: =+C14*D14 -> 0
B16: 2025
A17: ITEM | B17: TOTAL | C17: % | D17: COSTO POR TONELADA | E17: =+C14 -> 0 | F17: CF | G17: CV
A18: CUOTA ACERIAS | C18: =+B18*100%/B51 -> #DIV/0! | D18: =+B18/E17 -> #DIV/0! | E18: CF | F18: =+B18 -> 0
A19: ENERGIA | C19: =+B19*100%/B51 -> #DIV/0! | D19: =+B19/E17 -> #DIV/0! | E19: CV | G19: =+B19 -> 0
A20: COMBUSTIBLE | C20: =+B20*100%/B51 -> #DIV/0! | D20: =+B20/E17 -> #DIV/0! | E20: CV | G20: =+B20 -> 0
A21: MADERA | C21: =+B21*100%/B51 -> #DIV/0! | D21: =+B21/E17 -> #DIV/0! | E21: CV | G21: =+B21 -> 0
A22: NOMINA | C22: =+B22*100%/B51 -> #DIV/0! | D22: =+B22/E17 -> #DIV/0! | E22: CV | G22: =+B22 -> 0
A23: CARGA PRESTACI | C23: =+B23*100%/B51 -> #DIV/0! | D23: =+B23/E17 -> #DIV/0! | E23: CV | G23: =+B23 -> 0
A24: INSUMOS | C24: =+B24*100%/B51 -> #DIV/0! | D24: =+B24/E17 -> #DIV/0! | E24: CV | G24: =+B24 -> 0
A25: CALIBRACION | C25: =+B25*100%/B51 -> #DIV/0! | D25: =+B25/E17 -> #DIV/0! | E25: CV | G25: =+B25 -> 0
A26: ELEMEN ASEO | C26: =+B26*100%/B51 -> #DIV/0! | D26: =+B26/E17 -> #DIV/0! | E26: CF | F26: =+B26 -> 0
A27: DOTACION | C27: =+B27*100%/B51 -> #DIV/0! | D27: =+B27/E17 -> #DIV/0! | E27: CV | G27: =+B27 -> 0
A28: EXAMENES ING Y RETIRO | C28: =+B28*100%/B51 -> #DIV/0! | D28: =+B28/E17 -> #DIV/0! | E28: CV | G28: =+B28 -> 0
A29: PAPELERIA | C29: =+B29*100%/B51 -> #DIV/0! | D29: =+B29/E17 -> #DIV/0! | E29: CF | F29: =+B29 -> 0
A30: PEAJES | C30: =+B30*100%/B51 -> #DIV/0! | D30: =+B30/E17 -> #DIV/0! | E30: CV | G30: =+B30 -> 0
A31: TRANS PASA | C31: =+B31*100%/B51 -> #DIV/0! | D31: =+B31/E17 -> #DIV/0! | E31: CV | G31: =+B31 -> 0
A32: APORTES FEDERACION | C32: =+B32*100%/B51 -> #DIV/0! | D32: =+B32/E17 -> #DIV/0! | E32: CF | F32: =+B32 -> 0 | G32: 0
A33: VIATICOS | C33: =+B33*100%/B51 -> #DIV/0! | D33: =+B33/E17 -> #DIV/0! | E33: CV | G33: =+B33 -> 0
A34: RESTAURANTE | C34: =+B34*100%/B51 -> #DIV/0! | D34: =+B34/E17 -> #DIV/0! | E34: CV | G34: =+B34 -> 0
A35: MANT EQUIPOS | C35: =+B35*100%/B51 -> #DIV/0! | D35: =+B35/E17 -> #DIV/0! | E35: CF | F35: =+B35 -> 0 | G35: 0
A36: LEVANT TOPOGRAFICO | C36: =+B36*100%/B51 -> #DIV/0! | D36: =+B36/E17 -> #DIV/0! | E36: CF | F36: =+B36 -> 0
A37: TRANS CARBON | C37: =+B37*100%/B51 -> #DIV/0! | D37: =+B37/E17 -> #DIV/0! | E37: CF | F37: =+B37 -> 0
A38: TELEFONO | C38: =+B38*100%/B51 -> #DIV/0! | D38: =+B38/E17 -> #DIV/0! | E38: CF | F38: =+B38 -> 0
A39: POLIZA | C39: =+B39*100%/B51 -> #DIV/0! | D39: =+B39/E17 -> #DIV/0! | E39: CF | F39: =+B39 -> 0 | G39: 0
A40: VARIOS | C40: =+B40*100%/B51 -> #DIV/0! | D40: =+B40/E17 -> #DIV/0! | E40: CV | G40: =+B40 -> 0
A41: PUBLICIDAD | C41: =+B41*100%/B51 -> #DIV/0! | D41: =+B41/E17 -> #DIV/0! | E41: CV | G41: =+B41 -> 0
A42: INTERNET | C42: =+B42*100%/B51 -> #DIV/0! | D42: =+B42/E17 -> #DIV/0! | E42: CF | F42: =+B42 -> 0
A43: ASESORES EXTERNOS | C43: =+B43*100%/B51 -> #DIV/0! | D43: =+B43/E17 -> #DIV/0! | E43: CF | F43: =+B43 -> 0
A44: PAJARITA | C44: =+B44*100%/B51 -> #DIV/0! | D44: =+B44/E17 -> #DIV/0! | E44: CF | F44: =+B44 -> 0
A45: ARRIENDO | C45: =+B45*100%/B51 -> #DIV/0! | D45: =+B45/E17 -> #DIV/0! | E45: CF | F45: =+B45 -> 0
A46: % SERVIDUMBRE | C46: =+B46*100%/B51 -> #DIV/0! | D46: =+B46/E17 -> #DIV/0! | E46: CV | G46: =+B46 -> 0
A47: DEPRECIACION | C47: =+B47*100%/B51 -> #DIV/0! | D47: =+B47/E17 -> #DIV/0! | E47: CF | F47: =+B47 -> 0
A48: AUTORENTA | C48: =+B48*100%/B51 -> #DIV/0! | D48: =+B48/E17 -> #DIV/0! | E48: CV | G48: =+B48 -> 0
A49: GASTOS BANCARIOS | C49: =+B49*100%/B51 -> #DIV/0! | D49: =+B49/E17 -> #DIV/0! | E49: CF | F49: =+B49 -> 0
A50: PAGO REGALIAS | C50: =+B50*100%/B51 -> #DIV/0! | D50: =+B50/E17 -> #DIV/0! | E50: CV | G50: =+B50 -> 0
B51: =SUM(B18:B49) -> 0 | C51: =SUM(C18:C49) -> #DIV/0! | D51: =SUM(D18:D49) -> #DIV/0! | F51: =SUM(F18:F49) -> 0 | G51: =SUM(G19:G49) -> 0
B52: PE = CF / (P-CVU) | C52: PE | D52: =+F51/(293653-G52) -> #DIV/0! | F52: CVU | G52: =+G51/E17 -> #DIV/0!

Sheet JULIO
A13: PROCUCCION | B13: 0 | C13: PRODUCCION | D13: PRECIO VTA | E13: INGRESOS TOTALES
D14: 279000 | E14: =+C14*D14 -> 0
B16: 2025
A17: ITEM | B17: TOTAL | C17: % | D17: COSTO POR TONELADA | E17: =+C14 -> 0 | F17: CF | G17: CV
A18: CUOTA ACERIAS | C18: =+B18*100%/B51 -> #DIV/0! | D18: =+B18/E17 -> #DIV/0! | E18: CF | F18: =+B18 -> 0
A19: ENERGIA | C19: =+B19*100%/B51 -> #DIV/0! | D19: =+B19/E17 -> #DIV/0! | E19: CV | G19: =+B19 -> 0
A20: COMBUSTIBLE | C20: =+B20*100%/B51 -> #DIV/0! | D20: =+B20/E17 -> #DIV/0! | E20: CV | G20: =+B20 -> 0
A21: MADERA | C21: =+B21*100%/B51 -> #DIV/0! | D21: =+B21/E17 -> #DIV/0! | E21: CV | G21: =+B21 -> 0
A22: NOMINA | C22: =+B22*100%/B51 -> #DIV/0! | D22: =+B22/E17 -> #DIV/0! | E22: CV | G22: =+B22 -> 0
A23: CARGA PRESTACI | C23: =+B23*100%/B51 -> #DIV/0! | D23: =+B23/E17 -> #DIV/0! | E23: CV | G23: =+B23 -> 0
A24: INSUMOS | C24: =+B24*100%/B51 -> #DIV/0! | D24: =+B24/E17 -> #DIV/0! | E24: CV | G24: =+B24 -> 0
A25: CALIBRACION | C25: =+B25*100%/B51 -> #DIV/0! | D25: =+B25/E17 -> #DIV/0! | E25: CV | G25: =+B25 -> 0
A26: ELEMEN ASEO | C26: =+B26*100%/B51 -> #DIV/0! | D26: =+B26/E17 -> #DIV/0! | E26: CF | F26: =+B26 -> 0
A27: DOTACION | C27: =+B27*100%/B51 -> #DIV/0! | D27: =+B27/E17 -> #DIV/0! | E27: CV | G27: =+B27 -> 0
A28: EXAMENES ING Y RETIRO | C28: =+B28*100%/B51 -> #DIV/0! | D28: =+B28/E17 -> #DIV/0! | E28: CV | G28: =+B28 -> 0
A29: PAPELERIA | C29: =+B29*100%/B51 -> #DIV/0! | D29: =+B29/E17 -> #DIV/0! | E29: CF | F29: =+B29 -> 0
A30: PEAJES | C30: =+B30*100%/B51 -> #DIV/0! | D30: =+B30/E17 -> #DIV/0! | E30: CV | G30: =+B30 -> 0
A31: TRANS PASA | C31: =+B31*100%/B51 -> #DIV/0! | D31: =+B31/E17 -> #DIV/0! | E31: CV | G31: =+B31 -> 0
A32: APORTES FEDERACION | C32: =+B32*100%/B51 -> #DIV/0! | D32: =+B32/E17 -> #DIV/0! | E32: CF | F32: =+B32 -> 0 | G32: 0
A33: VIATICOS | C33: =+B33*100%/B51 -> #DIV/0! | D33: =+B33/E17 -> #DIV/0! | E33: CV | G33: =+B33 -> 0
A34: RESTAURANTE | C34: =+B34*100%/B51 -> #DIV/0! | D34: =+B34/E17 -> #DIV/0! | E34: CV | G34: =+B34 -> 0
A35: MANT EQUIPOS | C35: =+B35*100%/B51 -> #DIV/0! | D35: =+B35/E17 -> #DIV/0! | E35: CF | F35: =+B35 -> 0 | G35: 0
A36: LEVANT TOPOGRAFICO | C36: =+B36*100%/B51 -> #DIV/0! | D36: =+B36/E17 -> #DIV/0! | E36: CF | F36: =+B36 -> 0
A37: TRANS CARBON | C37: =+B37*100%/B51 -> #DIV/0! | D37: =+B37/E17 -> #DIV/0! | E37: CF | F37: =+B37 -> 0
A38: TELEFONO | C38: =+B38*100%/B51 -> #DIV/0! | D38: =+B38/E17 -> #DIV/0! | E38: CF | F38: =+B38 -> 0
A39: POLIZA | C39: =+B39*100%/B51 -> #DIV/0! | D39: =+B39/E17 -> #DIV/0! | E39: CF | F39: =+B39 -> 0 | G39: 0
A40: VARIOS | C40: =+B40*100%/B51 -> #DIV/0! | D40: =+B40/E17 -> #DIV/0! | E40: CV | G40: =+B40 -> 0
A41: PUBLICIDAD | C41: =+B41*100%/B51 -> #DIV/0! | D41: =+B41/E17 -> #DIV/0! | E41: CV | G41: =+B41 -> 0
A42: INTERNET | C42: =+B42*100%/B51 -> #DIV/0! | D42: =+B42/E17 -> #DIV/0! | E42: CF | F42: =+B42 -> 0
A43: ASESORES EXTERNOS | C43: =+B43*100%/B51 -> #DIV/0! | D43: =+B43/E17 -> #DIV/0! | E43: CF | F43: =+B43 -> 0
A44: PAJARITA | C44: =+B44*100%/B51 -> #DIV/0! | D44: =+B44/E17 -> #DIV/0! | E44: CF | F44: =+B44 -> 0
A45: ARRIENDO | C45: =+B45*100%/B51 -> #DIV/0! | D45: =+B45/E17 -> #DIV/0! | E45: CF | F45: =+B45 -> 0
A46: % SERVIDUMBRE | C46: =+B46*100%/B51 -> #DIV/0! | D46: =+B46/E17 -> #DIV/0! | E46: CV | G46: =+B46 -> 0
A47: DEPRECIACION | C47: =+B47*100%/B51 -> #DIV/0! | D47: =+B47/E17 -> #DIV/0! | E47: CF | F47: =+B47 -> 0
A48: AUTORENTA | C48: =+B48*100%/B51 -> #DIV/0! | D48: =+B48/E17 -> #DIV/0! | E48: CV | G48: =+B48 -> 0
A49: GASTOS BANCARIOS | C49: =+B49*100%/B51 -> #DIV/0! | D49: =+B49/E17 -> #DIV/0! | E49: CF | F49: =+B49 -> 0
A50: PAGO REGALIAS | C50: =+B50*100%/B51 -> #DIV/0! | D50: =+B50/E17 -> #DIV/0! | E50: CV | G50: =+B50 -> 0
B51: =SUM(B18:B50) -> 0 | C51: =SUM(C18:C50) -> #DIV/0! | D51: =SUM(D18:D49) -> #DIV/0! | F51: =SUM(F18:F50) -> 0 | G51: =SUM(G18:G50) -> 0
B52: PE = CF / (P-CVU) | C52: PE | D52: =+F51/(279000-G52) -> #DIV/0! | F52: CVU | G52: =+G51/E17 -> #DIV/0!

Sheet AGOSTO
A13: PROCUCCION | C13: PRODUCCION | D13: PRECIO VTA | E13: INGRESOS TOTALES
D14: 275000 | E14: =+C14*D14 -> 0
B16: 2025
A17: ITEM | B17: TOTAL | C17: % | D17: COSTO POR TONELADA | E17: =+C14 -> 0 | F17: CF | G17: CV
A18: CUOTA ACERIAS | C18: =+B18*100%/B51 -> #DIV/0! | D18: =+B18/E17 -> #DIV/0! | E18: CF | F18: =+B18 -> 0
A19: ENERGIA | C19: =+B19*100%/B51 -> #DIV/0! | D19: =+B19/E17 -> #DIV/0! | E19: CV | G19: =+B19 -> 0
A20: COMBUSTIBLE | C20: =+B20*100%/B51 -> #DIV/0! | D20: =+B20/E17 -> #DIV/0! | E20: CV | G20: =+B20 -> 0
A21: MADERA | C21: =+B21*100%/B51 -> #DIV/0! | D21: =+B21/E17 -> #DIV/0! | E21: CV | G21: =+B21 -> 0
A22: NOMINA | C22: =+B22*100%/B51 -> #DIV/0! | D22: =+B22/E17 -> #DIV/0! | E22: CV | G22: =+B22 -> 0
A23: CARGA PRESTACI | C23: =+B23*100%/B51 -> #DIV/0! | D23: =+B23/E17 -> #DIV/0! | E23: CV | G23: =+B23 -> 0
A24: INSUMOS | C24: =+B24*100%/B51 -> #DIV/0! | D24: =+B24/E17 -> #DIV/0! | E24: CV | G24: =+B24 -> 0
A25: CALIBRACION | C25: =+B25*100%/B51 -> #DIV/0! | D25: =+B25/E17 -> #DIV/0! | E25: CV | G25: =+B25 -> 0
A26: ELEMEN ASEO | C26: =+B26*100%/B51 -> #DIV/0! | D26: =+B26/E17 -> #DIV/0! | E26: CF | F26: =+B26 -> 0
A27: DOTACION | C27: =+B27*100%/B51 -> #DIV/0! | D27: =+B27/E17 -> #DIV/0! | E27: CV | G27: =+B27 -> 0
A28: EXAMENES ING Y RETIRO | C28: =+B28*100%/B51 -> #DIV/0! | D28: =+B28/E17 -> #DIV/0! | E28: CV | G28: =+B28 -> 0
A29: PAPELERIA | C29: =+B29*100%/B51 -> #DIV/0! | D29: =+B29/E17 -> #DIV/0! | E29: CF | F29: =+B29 -> 0
A30: PEAJES | C30: =+B30*100%/B51 -> #DIV/0! | D30: =+B30/E17 -> #DIV/0! | E30: CV | G30: =+B30 -> 0
A31: TRANS PASA | C31: =+B31*100%/B51 -> #DIV/0! | D31: =+B31/E17 -> #DIV/0! | E31: CV | G31: =+B31 -> 0
A32: APORTES FEDERACION | C32: =+B32*100%/B51 -> #DIV/0! | D32: =+B32/E17 -> #DIV/0! | E32: CF | F32: =+B32 -> 0 | G32: 0
A33: VIATICOS | C33: =+B33*100%/B51 -> #DIV/0! | D33: =+B33/E17 -> #DIV/0! | E33: CV | G33: =+B33 -> 0
A34: RESTAURANTE | C34: =+B34*100%/B51 -> #DIV/0! | D34: =+B34/E17 -> #DIV/0! | E34: CV | G34: =+B34 -> 0
A35: MANT EQUIPOS | C35: =+B35*100%/B51 -> #DIV/0! | D35: =+B35/E17 -> #DIV/0! | E35: CF | F35: =+B35 -> 0 | G35: 0
A36: LEVANT TOPOGRAFICO | C36: =+B36*100%/B51 -> #DIV/0! | D36: =+B36/E17 -> #DIV/0! | E36: CF | F36: =+B36 -> 0
A37: TRANS CARBON | C37: =+B37*100%/B51 -> #DIV/0! | D37: =+B37/E17 -> #DIV/0! | E37: CF | F37: =+B37 -> 0
A38: TELEFONO | C38: =+B38*100%/B51 -> #DIV/0! | D38: =+B38/E17 -> #DIV/0! | E38: CF | F38: =+B38 -> 0
A39: POLIZA | C39: =+B39*100%/B51 -> #DIV/0! | D39: =+B39/E17 -> #DIV/0! | E39: CF | F39: =+B39 -> 0 | G39: 0
A40: VARIOS | C40: =+B40*100%/B51 -> #DIV/0! | D40: =+B40/E17 -> #DIV/0! | E40: CV | G40: =+B40 -> 0
A41: PUBLICIDAD | C41: =+B41*100%/B51 -> #DIV/0! | D41: =+B41/E17 -> #DIV/0! | E41: CV | G41: =+B41 -> 0
A42: INTERNET | C42: =+B42*100%/B51 -> #DIV/0! | D42: =+B42/E17 -> #DIV/0! | E42: CF | F42: =+B42 -> 0
A43: ASESORES EXTERNOS | C43: =+B43*100%/B51 -> #DIV/0! | D43: =+B43/E17 -> #DIV/0! | E43: CF | F43: =+B43 -> 0
A44: PAJARITA | C44: =+B44*100%/B51 -> #DIV/0! | D44: =+B44/E17 -> #DIV/0! | E44: CF | F44: =+B44 -> 0
A45: ARRIENDO | C45: =+B45*100%/B51 -> #DIV/0! | D45: =+B45/E17 -> #DIV/0! | E45: CF | F45: =+B45 -> 0
A46: % SERVIDUMBRE | C46: =+B46*100%/B51 -> #DIV/0! | D46: =+B46/E17 -> #DIV/0! | E46: CV | G46: =+B46 -> 0
A47: DEPRECIACION | C47: =+B47*100%/B51 -> #DIV/0! | D47: =+B47/E17 -> #DIV/0! | E47: CF | F47: =+B47 -> 0
A48: AUTORENTA | C48: =+B48*100%/B51 -> #DIV/0! | D48: =+B48/E17 -> #DIV/0! | E48: CV | G48: =+B48 -> 0
A49: GASTOS BANCARIOS | C49: =+B49*100%/B51 -> #DIV/0! | D49: =+B49/E17 -> #DIV/0! | E49: CF | F49: =+B49 -> 0
A50: PAGO REGALIAS | C50: =+B50*100%/B51 -> #DIV/0! | D50: =+B50/E17 -> #DIV/0! | E50: CV | G50: =+B50 -> 0
B51: =SUM(B18:B50) -> 0 | C51: =SUM(C18:C50) -> #DIV/0! | D51: =SUM(D18:D50) -> #DIV/0! | F51: =SUM(F18:F50) -> 0 | G51: =SUM(G18:G50) -> 0
B52: PE = CF / (P-CVU) | C52: PE | D52: =+F51/(275000-G52) -> #DIV/0! | F52: CVU | G52: =+G51/E17 -> #DIV/0!

Sheet SEPTIEMBRE
A13: PROCUCCION | C13: PRODUCCION | D13: PRECIO VTA | E13: INGRESOS TOTALES
D14: 275000 | E14: =+C14*D14 -> 0
B16: 2025
A17: ITEM | B17: TOTAL | C17: % | D17: COSTO POR TONELADA | E17: =+C14 -> 0 | F17: CF | G17: CV
A18: CUOTA ACERIAS | C18: =+B18*100%/B51 -> #DIV/0! | D18: =+B18/E17 -> #DIV/0! | E18: CF | F18: =+B18 -> 0
A19: ENERGIA | C19: =+B19*100%/B51 -> #DIV/0! | D19: =+B19/E17 -> #DIV/0! | E19: CV | G19: =+B19 -> 0
A20: COMBUSTIBLE | C20: =+B20*100%/B51 -> #DIV/0! | D20: =+B20/E17 -> #DIV/0! | E20: CV | G20: =+B20 -> 0
A21: MADERA | C21: =+B21*100%/B51 -> #DIV/0! | D21: =+B21/E17 -> #DIV/0! | E21: CV | G21: =+B21 -> 0
A22: NOMINA | C22: =+B22*100%/B51 -> #DIV/0! | D22: =+B22/E17 -> #DIV/0! | E22: CV | G22: =+B22 -> 0
A23: CARGA PRESTACI | C23: =+B23*100%/B51 -> #DIV/0! | D23: =+B23/E17 -> #DIV/0! | E23: CV | G23: =+B23 -> 0
A24: INSUMOS | C24: =+B24*100%/B51 -> #DIV/0! | D24: =+B24/E17 -> #DIV/0! | E24: CV | G24: =+B24 -> 0
A25: CALIBRACION | C25: =+B25*100%/B51 -> #DIV/0! | D25: =+B25/E17 -> #DIV/0! | E25: CV | G25: =+B25 -> 0
A26: ELEMEN ASEO | C26: =+B26*100%/B51 -> #DIV/0! | D26: =+B26/E17 -> #DIV/0! | E26: CF | F26: =+B26 -> 0
A27: DOTACION | C27: =+B27*100%/B51 -> #DIV/0! | D27: =+B27/E17 -> #DIV/0! | E27: CV | G27: =+B27 -> 0
A28: EXAMENES ING Y RETIRO | C28: =+B28*100%/B51 -> #DIV/0! | D28: =+B28/E17 -> #DIV/0! | E28: CV | G28: =+B28 -> 0
A29: PAPELERIA | C29: =+B29*100%/B51 -> #DIV/0! | D29: =+B29/E17 -> #DIV/0! | E29: CF | F29: =+B29 -> 0
A30: PEAJES | C30: =+B30*100%/B51 -> #DIV/0! | D30: =+B30/E17 -> #DIV/0! | E30: CV | G30: =+B30 -> 0
A31: TRANS PASA | C31: =+B31*100%/B51 -> #DIV/0! | D31: =+B31/E17 -> #DIV/0! | E31: CV | G31: =+B31 -> 0
A32: APORTES FEDERACION | C32: =+B32*100%/B51 -> #DIV/0! | D32: =+B32/E17 -> #DIV/0! | E32: CF | F32: =+B32 -> 0 | G32: 0
A33: VIATICOS | C33: =+B33*100%/B51 -> #DIV/0! | D33: =+B33/E17 -> #DIV/0! | E33: CV | G33: =+B33 -> 0
A34: RESTAURANTE | C34: =+B34*100%/B51 -> #DIV/0! | D34: =+B34/E17 -> #DIV/0! | E34: CV | G34: =+B34 -> 0
A35: MANT EQUIPOS | C35: =+B35*100%/B51 -> #DIV/0! | D35: =+B35/E17 -> #DIV/0! | E35: CF | F35: =+B35 -> 0 | G35: 0
A36: LEVANT TOPOGRAFICO | C36: =+B36*100%/B51 -> #DIV/0! | D36: =+B36/E17 -> #DIV/0! | E36: CF | F36: =+B36 -> 0
A37: TRANS CARBON | C37: =+B37*100%/B51 -> #DIV/0! | D37: =+B37/E17 -> #DIV/0! | E37: CF | F37: =+B37 -> 0
A38: TELEFONO | C38: =+B38*100%/B51 -> #DIV/0! | D38: =+B38/E17 -> #DIV/0! | E38: CF | F38: =+B38 -> 0
A39: POLIZA | C39: =+B39*100%/B51 -> #DIV/0! | D39: =+B39/E17 -> #DIV/0! | E39: CF | F39: =+B39 -> 0 | G39: 0
A40: VARIOS | C40: =+B40*100%/B51 -> #DIV/0! | D40: =+B40/E17 -> #DIV/0! | E40: CV | G40: =+B40 -> 0
A41: PUBLICIDAD | C41: =+B41*100%/B51 -> #DIV/0! | D41: =+B41/E17 -> #DIV/0! | E41: CV | G41: =+B41 -> 0
A42: INTERNET | C42: =+B42*100%/B51 -> #DIV/0! | D42: =+B42/E17 -> #DIV/0! | E42: CF | F42: =+B42 -> 0
A43: ASESORES EXTERNOS | C43: =+B43*100%/B51 -> #DIV/0! | D43: =+B43/E17 -> #DIV/0! | E43: CF | F43: =+B43 -> 0
A44: PAJARITA | C44: =+B44*100%/B51 -> #DIV/0! | D44: =+B44/E17 -> #DIV/0! | E44: CF | F44: =+B44 -> 0
A45: ARRIENDO | C45: =+B45*100%/B51 -> #DIV/0! | D45: =+B45/E17 -> #DIV/0! | E45: CF | F45: =+B45 -> 0
A46: % SERVIDUMBRE | C46: =+B46*100%/B51 -> #DIV/0! | D46: =+B46/E17 -> #DIV/0! | E46: CV | G46: =+B46 -> 0
A47: DEPRECIACION | C47: =+B47*100%/B51 -> #DIV/0! | D47: =+B47/E17 -> #DIV/0! | E47: CF | F47: =+B47 -> 0
A48: AUTORENTA | C48: =+B48*100%/B51 -> #DIV/0! | D48: =+B48/E17 -> #DIV/0! | E48: CV | G48: =+B48 -> 0
A49: GASTOS BANCARIOS | C49: =+B49*100%/B51 -> #DIV/0! | D49: =+B49/E17 -> #DIV/0! | E49: CF | F49: =+B49 -> 0
A50: PAGO REGALIAS | C50: =+B50*100%/B51 -> #DIV/0! | D50: =+B50/E17 -> #DIV/0! | E50: CV | G50: =+B50 -> 0
B51: =SUM(B18:B50) -> 0 | C51: =SUM(C18:C50) -> #DIV/0! | D51: =SUM(D18:D50) -> #DIV/0! | E51: =SUM(E18:E50) -> 0 | F51: =SUM(F18:F50) -> 0 | G51: =SUM(G18:G50) -> 0
B52: PE = CF / (P-CVU) | C52: PE | D52: =+F51/(277000-G52) -> #DIV/0! | F52: CVU | G52: =+G51/E17 -> #DIV/0!

Sheet OCTUBRE 
A13: PROCUCCION | B13: =+'PRODUC ACUMULADA'!B14 -> 0 | C13: PRODUCCION | D13: PRECIO VTA | E13: INGRESOS TOTALES
C14: =+B13 -> 0 | D14: 270000 | E14: =+C14*D14 -> 0
B16: 2025
A17: ITEM | B17: TOTAL | C17: % | D17: COSTO POR TONELADA | E17: =+C14 -> 0 | F17: CF | G17: CV
A18: CUOTA ACERIAS | C18: =+B18*100%/B51 -> #DIV/0! | D18: =+B18/E17 -> #DIV/0! | E18: CF | F18: =+B18 -> 0
A19: ENERGIA | C19: =+B19*100%/B51 -> #DIV/0! | D19: =+B19/E17 -> #DIV/0! | E19: CV | G19: =+B19 -> 0
A20: COMBUSTIBLE | C20: =+B20*100%/B51 -> #DIV/0! | D20: =+B20/E17 -> #DIV/0! | E20: CV | G20: =+B20 -> 0
A21: MADERA | C21: =+B21*100%/B51 -> #DIV/0! | D21: =+B21/E17 -> #DIV/0! | E21: CV | G21: =+B21 -> 0
A22: NOMINA | C22: =+B22*100%/B51 -> #DIV/0! | D22: =+B22/E17 -> #DIV/0! | E22: CV | G22: =+B22 -> 0
A23: CARGA PRESTACI | C23: =+B23*100%/B51 -> #DIV/0! | D23: =+B23/E17 -> #DIV/0! | E23: CV | G23: =+B23 -> 0
A24: INSUMOS | C24: =+B24*100%/B51 -> #DIV/0! | D24: =+B24/E17 -> #DIV/0! | E24: CV | G24: =+B24 -> 0
A25: CALIBRACION | C25: =+B25*100%/B51 -> #DIV/0! | D25: =+B25/E17 -> #DIV/0! | E25: CV | G25: =+B25 -> 0
A26: ELEMEN ASEO | C26: =+B26*100%/B51 -> #DIV/0! | D26: =+B26/E17 -> #DIV/0! | E26: CF | F26: =+B26 -> 0
A27: DOTACION | C27: =+B27*100%/B51 -> #DIV/0! | D27: =+B27/E17 -> #DIV/0! | E27: CV | G27: =+B27 -> 0
A28: EXAMENES ING Y RETIRO | C28: =+B28*100%/B51 -> #DIV/0! | D28: =+B28/E17 -> #DIV/0! | E28: CV | G28: =+B28 -> 0
A29: PAPELERIA | C29: =+B29*100%/B51 -> #DIV/0! | D29: =+B29/E17 -> #DIV/0! | E29: CF | F29: =+B29 -> 0
A30: PEAJES | C30: =+B30*100%/B51 -> #DIV/0! | D30: =+B30/E17 -> #DIV/0! | E30: CV | G30: =+B30 -> 0
A31: TRANS PASA | C31: =+B31*100%/B51 -> #DIV/0! | D31: =+B31/E17 -> #DIV/0! | E31: CV | G31: =+B31 -> 0
A32: APORTES FEDERACION | C32: =+B32*100%/B51 -> #DIV/0! | D32: =+B32/E17 -> #DIV/0! | E32: CF | F32: =+B32 -> 0 | G32: 0
A33: VIATICOS | C33: =+B33*100%/B51 -> #DIV/0! | D33: =+B33/E17 -> #DIV/0! | E33: CV | G33: =+B33 -> 0
A34: RESTAURANTE | C34: =+B34*100%/B51 -> #DIV/0! | D34: =+B34/E17 -> #DIV/0! | E34: CV | G34: =+B34 -> 0
A35: MANT EQUIPOS | C35: =+B35*100%/B51 -> #DIV/0! | D35: =+B35/E17 -> #DIV/0! | E35: CF | F35: =+B35 -> 0 | G35: 0
A36: LEVANT TOPOGRAFICO | C36: =+B36*100%/B51 -> #DIV/0! | D36: =+B36/E17 -> #DIV/0! | E36: CF | F36: =+B36 -> 0
A37: TRANS CARBON | C37: =+B37*100%/B51 -> #DIV/0! | D37: =+B37/E17 -> #DIV/0! | E37: CF | F37: =+B37 -> 0
A38: TELEFONO | C38: =+B38*100%/B51 -> #DIV/0! | D38: =+B38/E17 -> #DIV/0! | E38: CF | F38: =+B38 -> 0
A39: POLIZA | C39: =+B39*100%/B51 -> #DIV/0! | D39: =+B39/E17 -> #DIV/0! | E39: CF | F39: =+B39 -> 0 | G39: 0
A40: VARIOS | C40: =+B40*100%/B51 -> #DIV/0! | D40: =+B40/E17 -> #DIV/0! | E40: CV | G40: =+B40 -> 0
A41: PUBLICIDAD | C41: =+B41*100%/B51 -> #DIV/0! | D41: =+B41/E17 -> #DIV/0! | E41: CV | G41: =+B41 -> 0
A42: INTERNET | C42: =+B42*100%/B51 -> #DIV/0! | D42: =+B42/E17 -> #DIV/0! | E42: CF | F42: =+B42 -> 0
A43: ASESORES EXTERNOS | C43: =+B43*100%/B51 -> #DIV/0! | D43: =+B43/E17 -> #DIV/0! | E43: CF | F43: =+B43 -> 0
A44: PAJARITA | C44: =+B44*100%/B51 -> #DIV/0! | D44: =+B44/E17 -> #DIV/0! | E44: CF | F44: =+B44 -> 0
A45: ARRIENDO | C45: =+B45*100%/B51 -> #DIV/0! | D45: =+B45/E17 -> #DIV/0! | E45: CF | F45: =+B45 -> 0
A46: % SERVIDUMBRE | C46: =+B46*100%/B51 -> #DIV/0! | D46: =+B46/E17 -> #DIV/0! | E46: CV | G46: =+B46 -> 0
A47: DEPRECIACION | C47: =+B47*100%/B51 -> #DIV/0! | D47: =+B47/E17 -> #DIV/0! | E47: CF | F47: =+B47 -> 0
A48: AUTORENTA | C48: =+B48*100%/B51 -> #DIV/0! | D48: =+B48/E17 -> #DIV/0! | E48: CV | G48: =+B48 -> 0
A49: GASTOS BANCARIOS | C49: =+B49*100%/B51 -> #DIV/0! | D49: =+B49/E17 -> #DIV/0! | E49: CF | F49: =+B49 -> 0
A50: PAGO REGALIAS | C50: =+B50*100%/B51 -> #DIV/0! | D50: =+B50/E17 -> #DIV/0! | E50: CV | G50: =+B50 -> 0
B51: =SUM(B18:B50) -> 0 | C51: =SUM(C18:C50) -> #DIV/0! | D51: =SUM(D18:D50) -> #DIV/0! | E51: =SUM(E18:E50) -> 0 | F51: =SUM(F18:F50) -> 0 | G51: =SUM(G18:G50) -> 0
B52: PE = CF / (P-CVU) | C52: PE | D52: =+F51/(277000-G52) -> #DIV/0! | F52: CVU | G52: =+G51/E17 -> #DIV/0!

Sheet EXPLOSIVO
B13: COSTOS PROYECTO SOCHA
A16: ENERO | B16: 0
A17: FEBRERO | B17: 0
A18: MARZO | B18: 0
A19: ABRIL | B19: 0
A20: MAYO | B20: 0
A21: JUNIO | B21: 0

Sheet RETROESCA
B13: COSTOS PROYECTO SOCHA
A16: ENERO | B16: 0
A17: FEBRERO | B17: 0
A18: MARZO | B18: 0
A19: ABRIL | B19: 0
A20: MAYO | B20: 0
A21: JUNIO | B21: 0

Sheet LABORAT
B13: COSTOS PROYECTO SOCHA
A16: ENERO | B16: 0
A17: FEBRERO | B17: 0
A18: MARZO | B18: 0
A19: ABRIL | B19: 0
A20: MAYO | B20: 0
A21: JUNIO | B21: 0

Sheet PAJARITA
B13: COSTOS PROYECTO SOCHA
A16: ENERO | B16: 0
A17: FEBRERO | B17: 0
A18: MARZO | B18: 0
A19: ABRIL | B19: 0
A20: MAYO | B20: 0
A21: JUNIO | B21: 0

Sheet NOVIEMBRE
A13: PROCUCCION | B13: =+'PRODUC ACUMULADA'!B15 -> 0 | C13: PRODUCCION | D13: PRECIO VTA | E13: INGRESOS TOTALES
C14: =+B13 -> 0 | D14: 270000 | E14: =+C14*D14 -> 0
B16: 2025
A17: ITEM | B17: TOTAL | C17: % | D17: COSTO POR TONELADA | E17: =+C14 -> 0 | F17: CF | G17: CV
A18: CUOTA ACERIAS | C18: =+B18*100%/B51 -> #DIV/0! | D18: =+B18/E17 -> #DIV/0! | E18: CF | F18: =+B18 -> 0
A19: ENERGIA | C19: =+B19*100%/B51 -> #DIV/0! | D19: =+B19/E17 -> #DIV/0! | E19: CV | G19: =+B19 -> 0
A20: COMBUSTIBLE | C20: =+B20*100%/B51 -> #DIV/0! | D20: =+B20/E17 -> #DIV/0! | E20: CV | G20: =+B20 -> 0
A21: MADERA | C21: =+B21*100%/B51 -> #DIV/0! | D21: =+B21/E17 -> #DIV/0! | E21: CV | G21: =+B21 -> 0
A22: NOMINA | C22: =+B22*100%/B51 -> #DIV/0! | D22: =+B22/E17 -> #DIV/0! | E22: CV | G22: =+B22 -> 0
A23: CARGA PRESTACI | C23: =+B23*100%/B51 -> #DIV/0! | D23: =+B23/E17 -> #DIV/0! | E23: CV | G23: =+B23 -> 0
A24: INSUMOS | C24: =+B24*100%/B51 -> #DIV/0! | D24: =+B24/E17 -> #DIV/0! | E24: CV | G24: =+B24 -> 0
A25: CALIBRACION | C25: =+B25*100%/B51 -> #DIV/0! | D25: =+B25/E17 -> #DIV/0! | E25: CV | G25: =+B25 -> 0
A26: ELEMEN ASEO | C26: =+B26*100%/B51 -> #DIV/0! | D26: =+B26/E17 -> #DIV/0! | E26: CF | F26: =+B26 -> 0
A27: DOTACION | C27: =+B27*100%/B51 -> #DIV/0! | D27: =+B27/E17 -> #DIV/0! | E27: CV | G27: =+B27 -> 0
A28: EXAMENES ING Y RETIRO | C28: =+B28*100%/B51 -> #DIV/0! | D28: =+B28/E17 -> #DIV/0! | E28: CV | G28: =+B28 -> 0
A29: PAPELERIA | C29: =+B29*100%/B51 -> #DIV/0! | D29: =+B29/E17 -> #DIV/0! | E29: CF | F29: =+B29 -> 0
A30: PEAJES | C30: =+B30*100%/B51 -> #DIV/0! | D30: =+B30/E17 -> #DIV/0! | E30: CV | G30: =+B30 -> 0
A31: TRANS PASA | C31: =+B31*100%/B51 -> #DIV/0! | D31: =+B31/E17 -> #DIV/0! | E31: CV | G31: =+B31 -> 0
A32: APORTES FEDERACION | C32: =+B32*100%/B51 -> #DIV/0! | D32: =+B32/E17 -> #DIV/0! | E32: CF | F32: =+B32 -> 0 | G32: 0
A33: VIATICOS | C33: =+B33*100%/B51 -> #DIV/0! | D33: =+B33/E17 -> #DIV/0! | E33: CV | G33: =+B33 -> 0
A34: RESTAURANTE | C34: =+B34*100%/B51 -> #DIV/0! | D34: =+B34/E17 -> #DIV/0! | E34: CV | G34: =+B34 -> 0
A35: MANT EQUIPOS | C35: =+B35*100%/B51 -> #DIV/0! | D35: =+B35/E17 -> #DIV/0! | E35: CF | F35: =+B35 -> 0 | G35: 0
A36: LEVANT TOPOGRAFICO | C36: =+B36*100%/B51 -> #DIV/0! | D36: =+B36/E17 -> #DIV/0! | E36: CF | F36: =+B36 -> 0
A37: TRANS CARBON | C37: =+B37*100%/B51 -> #DIV/0! | D37: =+B37/E17 -> #DIV/0! | E37: CF | F37: =+B37 -> 0
A38: TELEFONO | C38: =+B38*100%/B51 -> #DIV/0! | D38: =+B38/E17 -> #DIV/0! | E38: CF | F38: =+B38 -> 0
A39: POLIZA | C39: =+B39*100%/B51 -> #DIV/0! | D39: =+B39/E17 -> #DIV/0! | E39: CF | F39: =+B39 -> 0 | G39: 0
A40: VARIOS | C40: =+B40*100%/B51 -> #DIV/0! | D40: =+B40/E17 -> #DIV/0! | E40: CV | G40: =+B40 -> 0
A41: PUBLICIDAD | C41: =+B41*100%/B51 -> #DIV/0! | D41: =+B41/E17 -> #DIV/0! | E41: CV | G41: =+B41 -> 0
A42: INTERNET | C42: =+B42*100%/B51 -> #DIV/0! | D42: =+B42/E17 -> #DIV/0! | E42: CF | F42: =+B42 -> 0
A43: ASESORES EXTERNOS | C43: =+B43*100%/B51 -> #DIV/0! | D43: =+B43/E17 -> #DIV/0! | E43: CF | F43: =+B43 -> 0
A44: PAJARITA | C44: =+B44*100%/B51 -> #DIV/0! | D44: =+B44/E17 -> #DIV/0! | E44: CF | F44: =+B44 -> 0
A45: ARRIENDO | C45: =+B45*100%/B51 -> #DIV/0! | D45: =+B45/E17 -> #DIV/0! | E45: CF | F45: =+B45 -> 0
A46: % SERVIDUMBRE | C46: =+B46*100%/B51 -> #DIV/0! | D46: =+B46/E17 -> #DIV/0! | E46: CV | G46: =+B46 -> 0
A47: DEPRECIACION | C47: =+B47*100%/B51 -> #DIV/0! | D47: =+B47/E17 -> #DIV/0! | E47: CF | F47: =+B47 -> 0
A48: AUTORENTA | C48: =+B48*100%/B51 -> #DIV/0! | D48: =+B48/E17 -> #DIV/0! | E48: CV | G48: =+B48 -> 0
A49: GASTOS BANCARIOS | C49: =+B49*100%/B51 -> #DIV/0! | D49: =+B49/E17 -> #DIV/0! | E49: CF | F49: =+B49 -> 0
A50: PAGO REGALIAS | C50: =+B50*100%/B51 -> #DIV/0! | D50: =+B50/E17 -> #DIV/0! | E50: CV | G50: =+B50 -> 0
B51: =SUM(B18:B50) -> 0 | C51: =SUM(C18:C50) -> #DIV/0! | D51: =SUM(D18:D50) -> #DIV/0! | E51: =SUM(E18:E50) -> 0 | F51: =SUM(F18:F50) -> 0 | G51: =SUM(G18:G50) -> 0
B52: PE = CF / (P-CVU) | C52: PE | D52: =+F51/(277000-G52) -> #DIV/0! | F52: CVU | G52: =+G51/E17 -> #DIV/0!

Sheet DICIEMBRE
A13: PROCUCCION | C13: PRODUCCION | D13: PRECIO VTA | E13: INGRESOS TOTALES
D14: 280000 | E14: =+C14*D14 -> 0
B16: 2025
A17: ITEM | B17: TOTAL | C17: % | D17: COSTO POR TONELADA | E17: =+C14 -> 0 | F17: CF | G17: CV
A18: CUOTA ACERIAS | C18: =+B18*100%/B51 -> #DIV/0! | D18: =+B18/E17 -> #DIV/0! | E18: CF | F18: =+B18 -> 0
A19: ENERGIA | C19: =+B19*100%/B51 -> #DIV/0! | D19: =+B19/E17 -> #DIV/0! | E19: CV | G19: =+B19 -> 0
A20: COMBUSTIBLE | C20: =+B20*100%/B51 -> #DIV/0! | D20: =+B20/E17 -> #DIV/0! | E20: CV | G20: =+B20 -> 0
A21: MADERA | C21: =+B21*100%/B51 -> #DIV/0! | D21: =+B21/E17 -> #DIV/0! | E21: CV | G21: =+B21 -> 0
A22: NOMINA | C22: =+B22*100%/B51 -> #DIV/0! | D22: =+B22/E17 -> #DIV/0! | E22: CV | G22: =+B22 -> 0
A23: CARGA PRESTACI | C23: =+B23*100%/B51 -> #DIV/0! | D23: =+B23/E17 -> #DIV/0! | E23: CV | G23: =+B23 -> 0
A24: INSUMOS | C24: =+B24*100%/B51 -> #DIV/0! | D24: =+B24/E17 -> #DIV/0! | E24: CV | G24: =+B24 -> 0
A25: CALIBRACION | C25: =+B25*100%/B51 -> #DIV/0! | D25: =+B25/E17 -> #DIV/0! | E25: CV | G25: =+B25 -> 0
A26: ELEMEN ASEO | C26: =+B26*100%/B51 -> #DIV/0! | D26: =+B26/E17 -> #DIV/0! | E26: CF | F26: =+B26 -> 0
A27: DOTACION | C27: =+B27*100%/B51 -> #DIV/0! | D27: =+B27/E17 -> #DIV/0! | E27: CV | G27: =+B27 -> 0
A28: EXAMENES ING Y RETIRO | C28: =+B28*100%/B51 -> #DIV/0! | D28: =+B28/E17 -> #DIV/0! | E28: CV | G28: =+B28 -> 0
A29: PAPELERIA | C29: =+B29*100%/B51 -> #DIV/0! | D29: =+B29/E17 -> #DIV/0! | E29: CF | F29: =+B29 -> 0
A30: PEAJES | C30: =+B30*100%/B51 -> #DIV/0! | D30: =+B30/E17 -> #DIV/0! | E30: CV | G30: =+B30 -> 0
A31: TRANS PASA | C31: =+B31*100%/B51 -> #DIV/0! | D31: =+B31/E17 -> #DIV/0! | E31: CV | G31: =+B31 -> 0
A32: APORTES FEDERACION | C32: =+B32*100%/B51 -> #DIV/0! | D32: =+B32/E17 -> #DIV/0! | E32: CF | F32: =+B32 -> 0 | G32: 0
A33: VIATICOS | C33: =+B33*100%/B51 -> #DIV/0! | D33: =+B33/E17 -> #DIV/0! | E33: CV | G33: =+B33 -> 0
A34: RESTAURANTE | C34: =+B34*100%/B51 -> #DIV/0! | D34: =+B34/E17 -> #DIV/0! | E34: CV | G34: =+B34 -> 0
A35: MANT EQUIPOS | C35: =+B35*100%/B51 -> #DIV/0! | D35: =+B35/E17 -> #DIV/0! | E35: CF | F35: =+B35 -> 0 | G35: 0
A36: LEVANT TOPOGRAFICO | C36: =+B36*100%/B51 -> #DIV/0! | D36: =+B36/E17 -> #DIV/0! | E36: CF | F36: =+B36 -> 0
A37: TRANS CARBON | C37: =+B37*100%/B51 -> #DIV/0! | D37: =+B37/E17 -> #DIV/0! | E37: CF | F37: =+B37 -> 0
A38: TELEFONO | C38: =+B38*100%/B51 -> #DIV/0! | D38: =+B38/E17 -> #DIV/0! | E38: CF | F38: =+B38 -> 0
A39: POLIZA | C39: =+B39*100%/B51 -> #DIV/0! | D39: =+B39/E17 -> #DIV/0! | E39: CF | F39: =+B39 -> 0 | G39: 0
A40: VARIOS | C40: =+B40*100%/B51 -> #DIV/0! | D40: =+B40/E17 -> #DIV/0! | E40: CV | G40: =+B40 -> 0
A41: PUBLICIDAD | C41: =+B41*100%/B51 -> #DIV/0! | D41: =+B41/E17 -> #DIV/0! | E41: CV | G41: =+B41 -> 0
A42: INTERNET | C42: =+B42*100%/B51 -> #DIV/0! | D42: =+B42/E17 -> #DIV/0! | E42: CF | F42: =+B42 -> 0
A43: ASESORES EXTERNOS | C43: =+B43*100%/B51 -> #DIV/0! | D43: =+B43/E17 -> #DIV/0! | E43: CF | F43: =+B43 -> 0
A44: PAJARITA | C44: =+B44*100%/B51 -> #DIV/0! | D44: =+B44/E17 -> #DIV/0! | E44: CF | F44: =+B44 -> 0
A45: ARRIENDO | C45: =+B45*100%/B51 -> #DIV/0! | D45: =+B45/E17 -> #DIV/0! | E45: CF | F45: =+B45 -> 0
A46: % SERVIDUMBRE | C46: =+B46*100%/B51 -> #DIV/0! | D46: =+B46/E17 -> #DIV/0! | E46: CV | G46: =+B46 -> 0
A47: DEPRECIACION | C47: =+B47*100%/B51 -> #DIV/0! | D47: =+B47/E17 -> #DIV/0! | E47: CF | F47: =+B47 -> 0
A48: AUTORENTA | C48: =+B48*100%/B51 -> #DIV/0! | D48: =+B48/E17 -> #DIV/0! | E48: CV | G48: =+B48 -> 0
A49: GASTOS BANCARIOS | C49: =+B49*100%/B51 -> #DIV/0! | D49: =+B49/E17 -> #DIV/0! | E49: CF | F49: =+B49 -> 0
A50: PAGO REGALIAS | C50: =+B50*100%/B51 -> #DIV/0! | D50: =+B50/E17 -> #DIV/0! | E50: CV | G50: =+B50 -> 0
B51: =SUM(B18:B50) -> 0 | C51: =SUM(C18:C50) -> #DIV/0! | D51: =SUM(D18:D50) -> #DIV/0! | E51: =SUM(E18:E50) -> 0 | F51: =SUM(F18:F50) -> 0 | G51: =SUM(G18:G50) -> 0
B52: PE = CF / (P-CVU) | C52: PE | D52: =+F51/(280000-G52) -> #DIV/0! | F52: CVU | G52: =+G51/E17 -> #DIV/0!

Sheet PRODUC ACUMULADA
A2: PRODUCCION MES
A4: MES | B4: PRODUCCION
A5: ENERO | B5: =+'[6]PRODUC ACUMULADA'!$B$5 -> 1698.66
A6: FEBRERO | B6: =+[7]PRODUCCION!$B$15 -> 1830.15
A7: MARZO | B7: 1898.77
A8: ABRIL | B8: 1800.91
A9: MAYO | B9: =+'[8]PRODUC ACUMULADA'!$B$9 -> 1964.11
A10: JUNIO | B10: =+'[8]PRODUC ACUMULADA'!$B$10 -> 926.97
A11: JULIO | B11: 0
A12: AGOSTO | B12: 0
A13: SEPTIEMBRE | B13: 0
A14: OCTUBRE | B14: 0
A15: NOVIEMBRE | B15: 0
A16: DICIEMBRE | B16: 0
A17: TOTAL | B17: =SUM(B5:B16) -> 10119.57

Sheet INVERSIONES MINA
B13: COSTOS PROYECTO SOCHA
B15: 2020 | C15: 2021 | D15: 2022 | E15: 2023 | F15: 2024
A16: ENERO | B16: 0 | C16: =7400000+4280000+2340000+20000000+10000000 -> 44020000 | D16: =15351000+17960000 -> 33311000
A17: FEBRERO | C17: 12994800 | D17: 17050320 | E17: =5800000+31654000+8996535+5972000+8967304+5905275 -> 67295114
A18: MARZO | C18: =2000000+7000000+2925000 -> 11925000 | D18: =7996800+10162600 -> 18159400 | F18: 2380000
A19: ABRIL | D19: 24412400 | F19: 27000000
A20: MAYO | C20: 30830000 | D20: =46350284+1200000 -> 47550284 | E20: =168408800+16263500+15970000+181231649 -> 381873949
A21: JUNIO | C21: 800000 | D21: =2320500+27100000 -> 29420500 | E21: =41650000+4582452 -> 46232452
A22: JULIO | C22: 3625000 | D22: =14430000+13852790 -> 28282790
A23: AGOSTO | B23: 15655500 | C23: 45000000 | D23: =24492600+19040000+16567999 -> 60100599 | E23: 3600000
A24: SEPTIEMBRE | B24: 3900000 | C24: =6000000+6096000+100000000 -> 112096000 | D24: =11350000+30000000 -> 41350000
A25: OCTUBRE | C25: =12900000+15795250 -> 28695250 | D25: =40112377+9725454+15600900+24182883 -> 89621614 | E25: 0
A26: NOVIEMBRE | B26: 9282000 | C26: =9965000+7200000+123000000 -> 140165000
A27: DICIEMBRE | B27: =6200000+33000000 -> 39200000
A28: TOTAL DEF | B28: =SUM(B16:B27) -> 68037500 | C28: =SUM(C16:C27) -> 430151050 | D28: =SUM(D16:D27) -> 389258907 | E28: =SUM(E16:E27) -> 499001515 | F28: =SUM(F16:F27) -> 29380000

Sheet INFRAESTUCTURA
B13: COSTOS PROYECTO SOCHA
B15: 2020 | C15: 2021 | D15: 2022 | E15: 2023 | F15: 2024
A16: ENERO | B16: 0 | C16: =9242551+3500000+2001398 -> 14743949 | D16: 2571656
A17: FEBRERO | B17: 0 | C17: 10385641 | D17: =16734361+14115652 -> 30850013 | F17: 11498522
A18: MARZO | B18: 0 | C18: 7775367 | D18: 7318759 | E18: =3641400+2309641+22493702+5760667 -> 34205410 | F18: 4700000
A19: ABRIL | B19: 0 | C19: 0 | D19: =10800000+950000+27711399+16253165 -> 55714564 | E19: =30603833+396270+1160000+5760667 -> 37920770 | F19: =6058830 -> 6058830
A20: MAYO | B20: 0 | C20: 0 | D20: 39153111 | E20: =23796926+55760667 -> 79557593 | F20: =75276000+1410000 -> 76686000
A21: JUNIO | B21: 9858974 | C21: =39734694+6589128 -> 46323822 | D21: =2294100+16800000 -> 19094100 | E21: =18900029+17211975+17533333+5760667 -> 59406004 | F21: 620000
A22: JULIO | B22: 34036670 | C22: 3607224 | D22: 13746650 | E22: =14200000+3150000+802882+5760667 -> 23913549 | F22: 1159176
A23: AGOSTO | B23: =37694339+8000000 -> 45694339 | C23: 490557 | D23: =1503140 -> 1503140 | E23: =15623825+38275576+5760667 -> 59660068
A24: SEPTIEMBRE | B24: =102761469+5700000 -> 108461469 | C24: 5712930 | D24: 2308000 | E24: =8063970+5760667 -> 13824637
A25: OCTUBRE | B25: =7410596+9000000 -> 16410596 | C25: =9054611+1460000+5805334+926902 -> 17246847 | D25: =9866700 -> 9866700 | E25: =3603499+5760667 -> 9364166
A26: NOVIEMBRE | B26: =6449644+2880000+4000000 -> 13329644 | C26: 688000 | E26: =5760667+14311540 -> 20072207
A27: DICIEMBRE | B27: =980000+2772787+130000+590429+270000+4100000+9000000+65500000 -> 83343216 | C27: =952183+111025628 -> 111977811 | E27: =1702180+10115000 -> 11817180
A28: TOTAL DEF | B28: =SUM(B16:B27) -> 311134908 | C28: =SUM(C16:C27) -> 218952148 | D28: =SUM(D16:D27) -> 182126693 | E28: =SUM(E16:E27) -> 349741584 | F28: =SUM(F16:F27) -> 100722528

Sheet FACTURACION ACERIAS
B3: CONTROL DE FACTURAS RADICADAS 2023
B11: FACTURA | C11: DESCRIPCION | D11: TONELADAS | E11: V/R TONELADAS | F11: VALOR TOTAL | G11: DESCUENTOS | H11: VALOR A PAGAR | I11: RTF 2,5% | J11: CUOTA ACERIAS | K11: FECHA RADICADO | L11: VALOR A PAGAR DEF | M11: FECHA DE PAGO | N11: V/R CONSIG | O11: cruce | P11: MES CRUCE
B12: FV 242 | C12: SUMINISTRO DEL 14 al 19 enero 2026 | D12: 46.04 | E12: 310000 | F12: =+D12*E12 -> 14272400 | H12: =+F12-G12 -> 14272400 | I12: =+H12*2.5/100 -> 356810 | K12: 46044 | L12: =+H12-I12-J12 -> 13915590 | M12: 46105 | N12: 13210808
B13: FV 244 | C13: SUMINISTRO DEL 20 AL 27 ENERO | D13: 249.61 | E13: 308197 | F13: =+D13*E13 -> 76929053 | H13: =+F13-G13 -> 76929053 | I13: =+H13*2.5/100 -> 1923226.3 | K13: 46050 | L13: =+H13-I13-J13 -> 75005827 | M13: 46112 | N13: 27000000 | O13: 43616667 | P13: febrero
B14: FV 245 | C14: SUMINISTRO DEL 28 AL 31 ENERO | D14: 72.24 | E14: 310000 | F14: =+D14*E14 -> 22394400 | H14: =+F14-G14 -> 22394400 | I14: =+H14*2.5/100 -> 559860 | K14: 46058 | L14: =+H14-I14-J14 -> 21834540 | M14: 46119 | N14: 20728687
B15: FV 246 | C15: SUMINISTRO DEL 01 al 09 febrero | D15: 72.26 | E15: 310000 | F15: =+D15*E15 -> 22400600 | H15: =+F15-G15 -> 22400600 | I15: =+H15*2.5/100 -> 560015 | K15: 46058 | L15: =+H15-I15-J15 -> 21840585
B16: FV 248 | C16: SUMINISTRO DEL 25 AL 02 MARZO | D16: 207.27 | E16: 308379 | F16: =+D16*E16 -> 63917715 | H16: =+F16-G16 -> 63917715 | I16: =+H16*2.5/100 -> 1597942.9 | K16: 46058 | L16: =+H16-I16-J16 -> 62319772
